<?xml version="1.0"?>
<robot xmlns:xacro="http://www.ros.org/wiki/xacro">
  <xacro:include filename="$(find iiwa_description)/urdf/dual_arm_right.xacro" />
  <xacro:include filename="$(find iiwa_description)/urdf/dual_arm_left.xacro" />

  <xacro:macro name="dual_arm_manipulator" params="robot_name">
  <xacro:property name="joint_friction" value="0.005" />
  <xacro:property name="joint_damping" value="0.005" />
  <xacro:property name="PIhalf" value="1.570796" />
  <xacro:property name="PI" value="3.141592" />
  <link
    name="base_link">
    <inertial>
      <origin
        xyz="-0.0746188127206768 -5.55111512312578E-17 -0.0854799809858157"
        rpy="0 0 0" />
      <mass
        value="1.613834759363" />
      <inertia
        ixx="0"
        ixy="0"
        ixz="0"
        iyy="0"
        iyz="0"
        izz="0" />
    </inertial>
    <visual>
      <origin
        xyz="0 0 0"
        rpy="0 0 0" />
      <geometry>
        <mesh
          filename="package://iiwa_description/meshes/iiwa14/collision/Dual_Arm/base_link.STL" />
      </geometry>
      <material
        name="">
        <color
          rgba="1 1 1 1" />
      </material>
    </visual>
    <collision>
      <origin
        xyz="0 0 0"
        rpy="0 0 0" />
      <geometry>
        <mesh
          filename="package://iiwa_description/meshes/iiwa14/collision/Dual_Arm/base_link.STL" />
      </geometry>
    </collision>
  </link>
  <joint
    name="dual_arm_base_joint"
    type="revolute">
    <origin
      xyz="0 0 0.045"
      rpy="${PI} 0 0" />
    <parent
      link="${robot_name}_link_7" />
    <child
      link="base_link" />
    <axis
      xyz="0 0 1" />
    <limit
      lower="-3.14"
      upper="3.14"
      effort="20000"
      velocity="13" />
    <dynamics damping="${joint_damping}" friction = "${joint_friction}"/>
  </joint>
  <xacro:dual_arm_right robot_name="${robot_name}"/>
  <xacro:dual_arm_left robot_name="${robot_name}"/>
  </xacro:macro>
</robot>