<?xml version="1.0"?>
<robot xmlns:xacro="http://www.ros.org/wiki/xacro">
  <xacro:property name="joint_friction" value="0.005" />
  <xacro:property name="joint_damping" value="0.8" />
  <xacro:property name="PIhalf" value="1.570796" />
  <xacro:property name="PI" value="3.141592" />
  <xacro:macro name="dual_arm_right" params="robot_name">

  <joint
    name="J_R1"
    type="revolute">
    <origin
      xyz="-0.0744445637977397 -0.152871273073736 -0.110435575211296"
      rpy="1.7091 0.7757 0.1962" /> <!-- "1.43251148060093 -0.775712981728982 -2.94539473140516" -->
    <parent
      link="base_link" />
    <child
      link="Link_R1" />
    <axis
      xyz="0 0 1" />
    <limit
      lower="-${PI}"
      upper="${PI}"
      effort="20000"
      velocity="13" />
    <dynamics damping="${joint_damping}" friction = "${joint_friction}"/>
 </joint>
  <link
    name="Link_R1">
    <inertial>
      <origin
        xyz="0 -0.00002198 0.03386448"
        rpy="0 0 0" />
      <mass
        value="0.34855237" />
      <inertia
        ixx="0.00041198"
        ixy="0"
        ixz="0"
        iyy="0.00042179"
        iyz="-0.00000013"
        izy="-0.00000013"
        izz="0.00045583" />
    </inertial>
    <visual>
      <origin
        xyz="0 0 0"
        rpy="0 0 0" />
      <geometry>
        <mesh
          filename="package://iiwa_description/meshes/Dual_Arm_Manipulator/Arm/Link_1.STL" /> 
      </geometry><!--iiwa14/collision/Dual_Arm/Link1.STL-->
      <material
        name="">
        <color
          rgba="1 1 1 1" />
      </material>
    </visual>
    <collision>
      <origin
        xyz="0 0 0"
        rpy="0 0 0" />
      <geometry>
        <mesh
          filename="package://iiwa_description/meshes/Dual_Arm_Manipulator/Arm/Link_1_collision.STL" />
      </geometry>
    </collision>
  </link>
  
  <joint
    name="J_R2"
    type="revolute">
    <origin
      xyz="0 0 0.098815"
      rpy="-${PIhalf} 0 0" />
      <!-- "1.57079632679489 -0.380374098489847 0.317429885556193"-->
    <parent
      link="Link_R1" />
    <child
      link="Link_R2" />
    <axis
      xyz="0 0 1" />
    <limit
      lower="-${PI}"
      upper="${PI}"
      effort="20000"
      velocity="13" />
    <dynamics damping="${joint_damping}" friction = "${joint_friction}"/>
  </joint>

<link
    name="Link_R2">
    <inertial>
      <origin
        xyz="-0.00002616 -0.08182747 0.00586724"
        rpy="0 0 0" />
      <mass
        value=" 0.14210191" />
      <inertia
        ixx="0.00061848"
        ixy="0.00000018"
        ixz="0"
        iyx="0.00000018"
        iyy="0.00003828"
        iyz="-0.00005076"
        izy="-0.00005076"
        izz="0.00060901" />
    </inertial>
    <visual>
      <origin
        xyz="0 0 0"
        rpy="0 0 0" />
      <geometry>
        <mesh
          filename="package://iiwa_description/meshes/Dual_Arm_Manipulator/Arm/Link_2.STL" />
      </geometry>
      <material
        name="">
        <color
          rgba="0.898039215686275 0.898039215686275 0.898039215686275 1" />
      </material>
    </visual>
    <collision>
      <origin
        xyz="0 0 0"
        rpy="0 0 0" />
      <geometry>
        <mesh
          filename="package://iiwa_description/meshes/Dual_Arm_Manipulator/Arm/Link_2_collision.STL" />
      </geometry>
    </collision>
  </link>


  <joint
    name="J_R3"
    type="revolute">
    <origin
      xyz="0 -0.16645 0"
      rpy="${PIhalf} 0 0" />
      <!-- xyz="-0.178688999999999 -0.00012700000000021 0"
      rpy="-1.57079632679489 -1.0547118733939E-15 1.5707963267949"-->
    <parent
      link="Link_R2" />
    <child
      link="Link_R3" />
    <axis
      xyz="0 0 1" />
    <limit
      lower="-${PI}"
      upper="${PI}"
      effort="20000"
      velocity="13" />
    <dynamics damping="${joint_damping}" friction = "${joint_friction}"/>
  </joint>

  <link
    name="Link_R3">
    <inertial>
      <origin
        xyz="0.00018087 0 0.11630050"
        rpy="0 0 0" />
      <mass
        value="0.09637272" />
      <inertia
        ixx="0.00031529"
        ixy="0"
        ixz="0.00000077"
        iyy="0.00031517"
        iyz="0"
        izx="0.00000077"
        izz="0.00001827" />
    </inertial>
    <visual>
      <origin
        xyz="0 0 0"
        rpy="0 0 0" />
      <geometry>
        <mesh
          filename="package://iiwa_description/meshes/Dual_Arm_Manipulator/Arm/Link_3.STL" />
      </geometry>
      <material
        name="">
        <color
          rgba="1 1 1 1" />
      </material>
    </visual>
    <collision>
      <origin
        xyz="0 0 0"
        rpy="0 0 0" />
      <geometry>
        <mesh
          filename="package://iiwa_description/meshes/Dual_Arm_Manipulator/Arm/Link_3_collision.STL" />
      </geometry>
    </collision>
  </link>
 
  <joint
    name="J_R4"
    type="revolute">
    <origin
      xyz="-0.019005 0 0.1675"
      rpy="0 ${PIhalf} ${PI}" />
      <!--xyz="0.0266700000000004 0.0019050000000066 0.0609600000000012"
      rpy="-1.5707963267949 -0.824186362211141 -1.57079632679489"-->
    <parent
      link="Link_R3" />
    <child
      link="Link_R4" />
    <axis
      xyz="0 0 1" />
    <limit
      lower="-${PI}"
      upper="${PI}"
      effort="20000"
      velocity="13" />
    <dynamics damping="${joint_damping}" friction = "${joint_friction}"/>
  </joint>
 <link
    name="Link_R4">
      <inertial>
      <origin
        xyz=" -0.01338844 0 0.00944589"
        rpy="0 0 0" />
      <mass
        value="0.01812912" />
      <inertia
        ixx="0.00000196"
        ixy="0"
        ixz="-0.00000004"
        iyy="0.00000943"
        iyz="0"
        izx="-0.00000004"
        izz="0.00001043" />
    </inertial>
    <visual>
      <origin
        xyz="0 0 0"
        rpy="0 0 0" />
      <geometry>
        <mesh
          filename="package://iiwa_description/meshes/Dual_Arm_Manipulator/Arm/Link_4.STL" />
      </geometry>
      <material
        name="">
        <color
          rgba="1 1 1 1" />
      </material>
    </visual>
    <collision>
      <origin
        xyz="0 0 0"
        rpy="0 0 0" />
      <geometry>
        <mesh
          filename="package://iiwa_description/meshes/Dual_Arm_Manipulator/Arm/Link_4_collision.STL" />
      </geometry>
    </collision>
  </link>
  </xacro:macro>
</robot>