<sdf version='1.6'>
  <world name='default'>
    <light name='sun' type='directional'>
      <cast_shadows>1</cast_shadows>
      <pose frame=''>0 0 10 0 -0 0</pose>
      <diffuse>0.8 0.8 0.8 1</diffuse>
      <specular>0.2 0.2 0.2 1</specular>
      <attenuation>
        <range>1000</range>
        <constant>0.9</constant>
        <linear>0.01</linear>
        <quadratic>0.001</quadratic>
      </attenuation>
      <direction>-0.5 0.1 -0.9</direction>
    </light>
    <model name='ground_plane'>
      <static>1</static>
      <link name='link'>
        <collision name='collision'>
          <geometry>
            <plane>
              <normal>0 0 1</normal>
              <size>100 100</size>
            </plane>
          </geometry>
          <surface>
            <friction>
              <ode>
                <mu>100</mu>
                <mu2>50</mu2>
              </ode>
              <torsional>
                <ode/>
              </torsional>
            </friction>
            <contact>
              <ode/>
            </contact>
            <bounce/>
          </surface>
          <max_contacts>10</max_contacts>
        </collision>
        <visual name='visual'>
          <cast_shadows>0</cast_shadows>
          <geometry>
            <plane>
              <normal>0 0 1</normal>
              <size>100 100</size>
            </plane>
          </geometry>
          <material>
            <script>
              <uri>file://media/materials/scripts/gazebo.material</uri>
              <name>Gazebo/Grey</name>
            </script>
          </material>
        </visual>
        <self_collide>0</self_collide>
        <kinematic>0</kinematic>
      </link>
    </model>
    <gravity>0 0 -9.8</gravity>
    <magnetic_field>6e-06 2.3e-05 -4.2e-05</magnetic_field>
    <atmosphere type='adiabatic'/>
    <physics name='default_physics' default='0' type='ode'>
      <max_step_size>0.001</max_step_size>
      <real_time_factor>1</real_time_factor>
      <real_time_update_rate>1000</real_time_update_rate>
    </physics>
    <scene>
      <ambient>0.4 0.4 0.4 1</ambient>
      <background>0.7 0.7 0.7 1</background>
      <shadows>1</shadows>
    </scene>
    <spherical_coordinates>
      <surface_model>EARTH_WGS84</surface_model>
      <latitude_deg>0</latitude_deg>
      <longitude_deg>0</longitude_deg>
      <elevation>0</elevation>
      <heading_deg>0</heading_deg>
    </spherical_coordinates>
    <model name='iiwa14'>
      <link name='frame'>
        <pose frame=''>0 0 0 0 -0 0</pose>
        <inertial>
          <pose frame=''>1.5 0.25 1.25 0 -0 0</pose>
          <mass>2697</mass>
          <inertia>
            <ixx>0</ixx>
            <ixy>0</ixy>
            <ixz>0</ixz>
            <iyy>0</iyy>
            <iyz>0</iyz>
            <izz>0</izz>
          </inertia>
        </inertial>
        <collision name='frame_collision'>
          <pose frame=''>0 0 0 0 -0 0</pose>
          <geometry>
            <mesh>
              <scale>1 1 1</scale>
              <uri>/home/lasitha/Documents/ROS_ws/kuka_sim_ws/src/kuka-iiwa/iiwa_description/meshes/iiwa14/collision/base_link.STL</uri>
            </mesh>
          </geometry>
          <surface>
            <contact>
              <ode/>
            </contact>
            <friction>
              <ode>
                <mu>0.2</mu>
                <mu2>0.2</mu2>
              </ode>
              <torsional>
                <ode/>
              </torsional>
            </friction>
            <bounce/>
          </surface>
          <max_contacts>10</max_contacts>
        </collision>
        <visual name='frame_visual'>
          <pose frame=''>0 0 0 0 -0 0</pose>
          <geometry>
            <mesh>
              <scale>1 1 1</scale>
              <uri>/home/lasitha/Documents/ROS_ws/kuka_sim_ws/src/kuka-iiwa/iiwa_description/meshes/iiwa14/visual/base_link.STL</uri>
            </mesh>
          </geometry>
          <material>
            <script>
              <name>Gazebo/Orange</name>
              <uri>file://media/materials/scripts/gazebo.material</uri>
            </script>
          </material>
        </visual>
        <gravity>1</gravity>
        <velocity_decay/>
        <self_collide>0</self_collide>
        <kinematic>0</kinematic>
      </link>
      <joint name='fixed' type='fixed'>
        <child>frame</child>
        <parent>world</parent>
      </joint>
      <link name='surface'>
        <pose frame=''>1.5 0.25 0 0 -0 1.5707</pose>
        <inertial>
          <pose frame=''>0 0 0.0015 0 -0 0</pose>
          <mass>3.645</mass>
          <inertia>
            <ixx>0.0276</ixx>
            <ixy>0</ixy>
            <ixz>0</ixz>
            <iyy>0.00711</iyy>
            <iyz>0</iyz>
            <izz>0.03417</izz>
          </inertia>
        </inertial>
        <collision name='surface_collision'>
          <pose frame=''>0 0 0 0 -0 0</pose>
          <geometry>
            <mesh>
              <scale>1 1 1</scale>
              <uri>/home/lasitha/Documents/ROS_ws/kuka_sim_ws/src/kuka-iiwa/iiwa_description/meshes/iiwa14/collision/Pulsating Surface/Surface.STL</uri>
            </mesh>
          </geometry>
          <surface>
            <contact>
              <ode>
                <kp>10000</kp>
                <kd>2500</kd>
              </ode>
            </contact>
            <friction>
              <ode>
                <mu>0.2</mu>
                <mu2>0.2</mu2>
              </ode>
              <torsional>
                <ode/>
              </torsional>
            </friction>
            <bounce/>
          </surface>
          <max_contacts>10</max_contacts>
        </collision>
        <visual name='surface_visual'>
          <pose frame=''>0 0 0 0 -0 0</pose>
          <geometry>
            <mesh>
              <scale>1 1 1</scale>
              <uri>/home/lasitha/Documents/ROS_ws/kuka_sim_ws/src/kuka-iiwa/iiwa_description/meshes/iiwa14/collision/Pulsating Surface/Surface.STL</uri>
            </mesh>
          </geometry>
          <material>
            <script>
              <name>Gazebo/Orange</name>
              <uri>file://media/materials/scripts/gazebo.material</uri>
            </script>
          </material>
        </visual>
        <gravity>1</gravity>
        <velocity_decay/>
        <self_collide>0</self_collide>
        <kinematic>0</kinematic>
      </link>
      <joint name='prismatic_joint' type='prismatic'>
        <child>surface</child>
        <parent>world</parent>
        <axis>
          <xyz>0 0 1</xyz>
          <limit>
            <lower>-0.8</lower>
            <upper>0.3</upper>
            <effort>10000</effort>
            <velocity>10000</velocity>
          </limit>
          <dynamics>
            <damping>1</damping>
            <friction>1</friction>
            <spring_reference>0</spring_reference>
            <spring_stiffness>0</spring_stiffness>
          </dynamics>
          <use_parent_model_frame>1</use_parent_model_frame>
        </axis>
      </joint>
      <link name='iiwa_link_0'>
        <pose frame=''>1.5 0.25 1.9 3.14159 -0 0</pose>
        <inertial>
          <pose frame=''>-0.1 0 0.07 0 -0 0</pose>
          <mass>5</mass>
          <inertia>
            <ixx>0.05</ixx>
            <ixy>0</ixy>
            <ixz>0</ixz>
            <iyy>0.06</iyy>
            <iyz>0</iyz>
            <izz>0.03</izz>
          </inertia>
        </inertial>
        <collision name='iiwa_link_0_collision'>
          <pose frame=''>0 0 0 0 -0 0</pose>
          <geometry>
            <mesh>
              <scale>1 1 1</scale>
              <uri>/home/lasitha/Documents/ROS_ws/kuka_sim_ws/src/kuka-iiwa/iiwa_description/meshes/iiwa14/collision/link_0.stl</uri>
            </mesh>
          </geometry>
          <surface>
            <contact>
              <ode/>
            </contact>
            <friction>
              <ode>
                <mu>0.2</mu>
                <mu2>0.2</mu2>
              </ode>
              <torsional>
                <ode/>
              </torsional>
            </friction>
            <bounce/>
          </surface>
          <max_contacts>10</max_contacts>
        </collision>
        <visual name='iiwa_link_0_visual'>
          <pose frame=''>0 0 0 0 -0 0</pose>
          <geometry>
            <mesh>
              <scale>1 1 1</scale>
              <uri>/home/lasitha/Documents/ROS_ws/kuka_sim_ws/src/kuka-iiwa/iiwa_description/meshes/iiwa14/visual/link_0.stl</uri>
            </mesh>
          </geometry>
          <material>
            <script>
              <name>Gazebo/Grey</name>
              <uri>file://media/materials/scripts/gazebo.material</uri>
            </script>
          </material>
        </visual>
        <gravity>1</gravity>
        <velocity_decay/>
        <self_collide>0</self_collide>
        <kinematic>0</kinematic>
      </link>
      <joint name='world_iiwa_joint' type='fixed'>
        <child>iiwa_link_0</child>
        <parent>world</parent>
      </joint>
      <link name='iiwa_link_1'>
        <pose frame=''>1.5 0.25 1.7425 3.14159 -0 0</pose>
        <inertial>
          <pose frame=''>0 -0.03 0.12 0 -0 0</pose>
          <mass>4</mass>
          <inertia>
            <ixx>0.1</ixx>
            <ixy>0</ixy>
            <ixz>0</ixz>
            <iyy>0.09</iyy>
            <iyz>0</iyz>
            <izz>0.02</izz>
          </inertia>
        </inertial>
        <collision name='iiwa_link_1_collision'>
          <pose frame=''>0 0 0 0 -0 0</pose>
          <geometry>
            <mesh>
              <scale>1 1 1</scale>
              <uri>/home/lasitha/Documents/ROS_ws/kuka_sim_ws/src/kuka-iiwa/iiwa_description/meshes/iiwa14/collision/link_1.stl</uri>
            </mesh>
          </geometry>
          <surface>
            <contact>
              <ode/>
            </contact>
            <friction>
              <ode>
                <mu>0.2</mu>
                <mu2>0.2</mu2>
              </ode>
              <torsional>
                <ode/>
              </torsional>
            </friction>
            <bounce/>
          </surface>
          <max_contacts>10</max_contacts>
        </collision>
        <visual name='iiwa_link_1_visual'>
          <pose frame=''>0 0 0 0 -0 0</pose>
          <geometry>
            <mesh>
              <scale>1 1 1</scale>
              <uri>/home/lasitha/Documents/ROS_ws/kuka_sim_ws/src/kuka-iiwa/iiwa_description/meshes/iiwa14/visual/link_1.stl</uri>
            </mesh>
          </geometry>
          <material>
            <script>
              <name>Gazebo/White</name>
              <uri>file://media/materials/scripts/gazebo.material</uri>
            </script>
          </material>
        </visual>
        <gravity>1</gravity>
        <velocity_decay/>
        <self_collide>0</self_collide>
        <kinematic>0</kinematic>
      </link>
      <joint name='iiwa_joint_1' type='revolute'>
        <child>iiwa_link_1</child>
        <parent>iiwa_link_0</parent>
        <axis>
          <xyz>0 0 -1</xyz>
          <limit>
            <lower>-2.96706</lower>
            <upper>2.96706</upper>
            <effort>5000</effort>
            <velocity>100</velocity>
          </limit>
          <dynamics>
            <damping>0.4</damping>
            <friction>0.4</friction>
            <spring_reference>0</spring_reference>
            <spring_stiffness>0</spring_stiffness>
          </dynamics>
          <use_parent_model_frame>1</use_parent_model_frame>
        </axis>
      </joint>
      <link name='iiwa_link_2'>
        <pose frame=''>1.5 0.25 1.54 -1.5708 -0 3.14159</pose>
        <inertial>
          <pose frame=''>0.0003 0.059 0.042 0 -0 0</pose>
          <mass>4</mass>
          <inertia>
            <ixx>0.05</ixx>
            <ixy>0</ixy>
            <ixz>0</ixz>
            <iyy>0.018</iyy>
            <iyz>0</iyz>
            <izz>0.044</izz>
          </inertia>
        </inertial>
        <collision name='iiwa_link_2_collision'>
          <pose frame=''>0 0 0 0 -0 0</pose>
          <geometry>
            <mesh>
              <scale>1 1 1</scale>
              <uri>/home/lasitha/Documents/ROS_ws/kuka_sim_ws/src/kuka-iiwa/iiwa_description/meshes/iiwa14/collision/link_2.stl</uri>
            </mesh>
          </geometry>
          <surface>
            <contact>
              <ode/>
            </contact>
            <friction>
              <ode>
                <mu>0.2</mu>
                <mu2>0.2</mu2>
              </ode>
              <torsional>
                <ode/>
              </torsional>
            </friction>
            <bounce/>
          </surface>
          <max_contacts>10</max_contacts>
        </collision>
        <visual name='iiwa_link_2_visual'>
          <pose frame=''>0 0 0 0 -0 0</pose>
          <geometry>
            <mesh>
              <scale>1 1 1</scale>
              <uri>/home/lasitha/Documents/ROS_ws/kuka_sim_ws/src/kuka-iiwa/iiwa_description/meshes/iiwa14/visual/link_2.stl</uri>
            </mesh>
          </geometry>
          <material>
            <script>
              <name>Gazebo/White</name>
              <uri>file://media/materials/scripts/gazebo.material</uri>
            </script>
          </material>
        </visual>
        <gravity>1</gravity>
        <velocity_decay/>
        <self_collide>0</self_collide>
        <kinematic>0</kinematic>
      </link>
      <joint name='iiwa_joint_2' type='revolute'>
        <child>iiwa_link_2</child>
        <parent>iiwa_link_1</parent>
        <axis>
          <xyz>0 -1 0</xyz>
          <limit>
            <lower>-2.0944</lower>
            <upper>2.0944</upper>
            <effort>5000</effort>
            <velocity>100</velocity>
          </limit>
          <dynamics>
            <damping>0.4</damping>
            <friction>0.4</friction>
            <spring_reference>0</spring_reference>
            <spring_stiffness>0</spring_stiffness>
          </dynamics>
          <use_parent_model_frame>1</use_parent_model_frame>
        </axis>
      </joint>
      <link name='iiwa_link_3'>
        <pose frame=''>1.5 0.25 1.3355 3.14159 -0 0</pose>
        <inertial>
          <pose frame=''>0 0.03 0.13 0 -0 0</pose>
          <mass>3</mass>
          <inertia>
            <ixx>0.08</ixx>
            <ixy>0</ixy>
            <ixz>0</ixz>
            <iyy>0.075</iyy>
            <iyz>0</iyz>
            <izz>0.01</izz>
          </inertia>
        </inertial>
        <collision name='iiwa_link_3_collision'>
          <pose frame=''>0 0 0 0 -0 0</pose>
          <geometry>
            <mesh>
              <scale>1 1 1</scale>
              <uri>/home/lasitha/Documents/ROS_ws/kuka_sim_ws/src/kuka-iiwa/iiwa_description/meshes/iiwa14/collision/link_3.stl</uri>
            </mesh>
          </geometry>
          <surface>
            <contact>
              <ode/>
            </contact>
            <friction>
              <ode>
                <mu>0.2</mu>
                <mu2>0.2</mu2>
              </ode>
              <torsional>
                <ode/>
              </torsional>
            </friction>
            <bounce/>
          </surface>
          <max_contacts>10</max_contacts>
        </collision>
        <visual name='iiwa_link_3_visual'>
          <pose frame=''>0 0 0 0 -0 0</pose>
          <geometry>
            <mesh>
              <scale>1 1 1</scale>
              <uri>/home/lasitha/Documents/ROS_ws/kuka_sim_ws/src/kuka-iiwa/iiwa_description/meshes/iiwa14/visual/link_3.stl</uri>
            </mesh>
          </geometry>
          <material>
            <script>
              <name>Gazebo/White</name>
              <uri>file://media/materials/scripts/gazebo.material</uri>
            </script>
          </material>
        </visual>
        <gravity>1</gravity>
        <velocity_decay/>
        <self_collide>0</self_collide>
        <kinematic>0</kinematic>
      </link>
      <joint name='iiwa_joint_3' type='revolute'>
        <child>iiwa_link_3</child>
        <parent>iiwa_link_2</parent>
        <axis>
          <xyz>0 0 -1</xyz>
          <limit>
            <lower>-2.96706</lower>
            <upper>2.96706</upper>
            <effort>5000</effort>
            <velocity>100</velocity>
          </limit>
          <dynamics>
            <damping>0.4</damping>
            <friction>0.4</friction>
            <spring_reference>0</spring_reference>
            <spring_stiffness>0</spring_stiffness>
          </dynamics>
          <use_parent_model_frame>1</use_parent_model_frame>
        </axis>
      </joint>
      <link name='iiwa_link_4'>
        <pose frame=''>1.5 0.25 1.12 -1.5708 -0 -0</pose>
        <inertial>
          <pose frame=''>0 0.067 0.034 0 -0 0</pose>
          <mass>2.7</mass>
          <inertia>
            <ixx>0.03</ixx>
            <ixy>0</ixy>
            <ixz>0</ixz>
            <iyy>0.01</iyy>
            <iyz>0</iyz>
            <izz>0.029</izz>
          </inertia>
        </inertial>
        <collision name='iiwa_link_4_collision'>
          <pose frame=''>0 0 0 0 -0 0</pose>
          <geometry>
            <mesh>
              <scale>1 1 1</scale>
              <uri>/home/lasitha/Documents/ROS_ws/kuka_sim_ws/src/kuka-iiwa/iiwa_description/meshes/iiwa14/collision/link_4.stl</uri>
            </mesh>
          </geometry>
          <surface>
            <contact>
              <ode/>
            </contact>
            <friction>
              <ode>
                <mu>0.2</mu>
                <mu2>0.2</mu2>
              </ode>
              <torsional>
                <ode/>
              </torsional>
            </friction>
            <bounce/>
          </surface>
          <max_contacts>10</max_contacts>
        </collision>
        <visual name='iiwa_link_4_visual'>
          <pose frame=''>0 0 0 0 -0 0</pose>
          <geometry>
            <mesh>
              <scale>1 1 1</scale>
              <uri>/home/lasitha/Documents/ROS_ws/kuka_sim_ws/src/kuka-iiwa/iiwa_description/meshes/iiwa14/visual/link_4.stl</uri>
            </mesh>
          </geometry>
          <material>
            <script>
              <name>Gazebo/White</name>
              <uri>file://media/materials/scripts/gazebo.material</uri>
            </script>
          </material>
        </visual>
        <gravity>1</gravity>
        <velocity_decay/>
        <self_collide>0</self_collide>
        <kinematic>0</kinematic>
      </link>
      <joint name='iiwa_joint_4' type='revolute'>
        <child>iiwa_link_4</child>
        <parent>iiwa_link_3</parent>
        <axis>
          <xyz>0 1 0</xyz>
          <limit>
            <lower>-2.0944</lower>
            <upper>2.0944</upper>
            <effort>5000</effort>
            <velocity>100</velocity>
          </limit>
          <dynamics>
            <damping>0.4</damping>
            <friction>0.4</friction>
            <spring_reference>0</spring_reference>
            <spring_stiffness>0</spring_stiffness>
          </dynamics>
          <use_parent_model_frame>1</use_parent_model_frame>
        </axis>
      </joint>
      <link name='iiwa_link_5'>
        <pose frame=''>1.5 0.25 0.9355 -3.14159 -0 3.14159</pose>
        <inertial>
          <pose frame=''>0.0001 0.021 0.076 0 -0 0</pose>
          <mass>1.7</mass>
          <inertia>
            <ixx>0.02</ixx>
            <ixy>0</ixy>
            <ixz>0</ixz>
            <iyy>0.018</iyy>
            <iyz>0</iyz>
            <izz>0.005</izz>
          </inertia>
        </inertial>
        <collision name='iiwa_link_5_collision'>
          <pose frame=''>0 0 0 0 -0 0</pose>
          <geometry>
            <mesh>
              <scale>1 1 1</scale>
              <uri>/home/lasitha/Documents/ROS_ws/kuka_sim_ws/src/kuka-iiwa/iiwa_description/meshes/iiwa14/collision/link_5.stl</uri>
            </mesh>
          </geometry>
          <surface>
            <contact>
              <ode/>
            </contact>
            <friction>
              <ode>
                <mu>0.2</mu>
                <mu2>0.2</mu2>
              </ode>
              <torsional>
                <ode/>
              </torsional>
            </friction>
            <bounce/>
          </surface>
          <max_contacts>10</max_contacts>
        </collision>
        <visual name='iiwa_link_5_visual'>
          <pose frame=''>0 0 0 0 -0 0</pose>
          <geometry>
            <mesh>
              <scale>1 1 1</scale>
              <uri>/home/lasitha/Documents/ROS_ws/kuka_sim_ws/src/kuka-iiwa/iiwa_description/meshes/iiwa14/visual/link_5.stl</uri>
            </mesh>
          </geometry>
          <material>
            <script>
              <name>Gazebo/White</name>
              <uri>file://media/materials/scripts/gazebo.material</uri>
            </script>
          </material>
        </visual>
        <gravity>1</gravity>
        <velocity_decay/>
        <self_collide>0</self_collide>
        <kinematic>0</kinematic>
      </link>
      <joint name='iiwa_joint_5' type='revolute'>
        <child>iiwa_link_5</child>
        <parent>iiwa_link_4</parent>
        <axis>
          <xyz>0 0 -1</xyz>
          <limit>
            <lower>-2.96706</lower>
            <upper>2.96706</upper>
            <effort>5000</effort>
            <velocity>100</velocity>
          </limit>
          <dynamics>
            <damping>0.4</damping>
            <friction>0.4</friction>
            <spring_reference>0</spring_reference>
            <spring_stiffness>0</spring_stiffness>
          </dynamics>
          <use_parent_model_frame>1</use_parent_model_frame>
        </axis>
      </joint>
      <link name='iiwa_link_6'>
        <pose frame=''>1.5 0.25 0.72 -1.5708 -0 3.14159</pose>
        <inertial>
          <pose frame=''>0 0.0006 0.0004 0 -0 0</pose>
          <mass>1.8</mass>
          <inertia>
            <ixx>0.005</ixx>
            <ixy>0</ixy>
            <ixz>0</ixz>
            <iyy>0.0036</iyy>
            <iyz>0</iyz>
            <izz>0.0047</izz>
          </inertia>
        </inertial>
        <collision name='iiwa_link_6_collision'>
          <pose frame=''>0 0 0 0 -0 0</pose>
          <geometry>
            <mesh>
              <scale>1 1 1</scale>
              <uri>/home/lasitha/Documents/ROS_ws/kuka_sim_ws/src/kuka-iiwa/iiwa_description/meshes/iiwa14/collision/link_6.stl</uri>
            </mesh>
          </geometry>
          <surface>
            <contact>
              <ode/>
            </contact>
            <friction>
              <ode>
                <mu>0.2</mu>
                <mu2>0.2</mu2>
              </ode>
              <torsional>
                <ode/>
              </torsional>
            </friction>
            <bounce/>
          </surface>
          <max_contacts>10</max_contacts>
        </collision>
        <visual name='iiwa_link_6_visual'>
          <pose frame=''>0 0 0 0 -0 0</pose>
          <geometry>
            <mesh>
              <scale>1 1 1</scale>
              <uri>/home/lasitha/Documents/ROS_ws/kuka_sim_ws/src/kuka-iiwa/iiwa_description/meshes/iiwa14/visual/link_6.stl</uri>
            </mesh>
          </geometry>
          <material>
            <script>
              <name>Gazebo/White</name>
              <uri>file://media/materials/scripts/gazebo.material</uri>
            </script>
          </material>
        </visual>
        <gravity>1</gravity>
        <velocity_decay/>
        <self_collide>0</self_collide>
        <kinematic>0</kinematic>
      </link>
      <joint name='iiwa_joint_6' type='revolute'>
        <child>iiwa_link_6</child>
        <parent>iiwa_link_5</parent>
        <axis>
          <xyz>0 -1 0</xyz>
          <limit>
            <lower>-2.0944</lower>
            <upper>2.0944</upper>
            <effort>5000</effort>
            <velocity>100</velocity>
          </limit>
          <dynamics>
            <damping>0.4</damping>
            <friction>0.4</friction>
            <spring_reference>0</spring_reference>
            <spring_stiffness>0</spring_stiffness>
          </dynamics>
          <use_parent_model_frame>1</use_parent_model_frame>
        </axis>
      </joint>
      <link name='iiwa_link_7'>
        <pose frame=''>1.5 0.25 0.639 3.14159 -0 0</pose>
        <inertial>
          <pose frame=''>0 0 0.02 0 -0 0</pose>
          <mass>0.3</mass>
          <inertia>
            <ixx>0.001</ixx>
            <ixy>0</ixy>
            <ixz>0</ixz>
            <iyy>0.001</iyy>
            <iyz>0</iyz>
            <izz>0.001</izz>
          </inertia>
        </inertial>
        <collision name='iiwa_link_7_collision'>
          <pose frame=''>0 0 0 0 -0 0</pose>
          <geometry>
            <mesh>
              <scale>1 1 1</scale>
              <uri>/home/lasitha/Documents/ROS_ws/kuka_sim_ws/src/kuka-iiwa/iiwa_description/meshes/iiwa14/collision/link_7.stl</uri>
            </mesh>
          </geometry>
          <surface>
            <contact>
              <ode/>
            </contact>
            <friction>
              <ode>
                <mu>0.2</mu>
                <mu2>0.2</mu2>
              </ode>
              <torsional>
                <ode/>
              </torsional>
            </friction>
            <bounce/>
          </surface>
          <max_contacts>10</max_contacts>
        </collision>
        <visual name='iiwa_link_7_visual'>
          <pose frame=''>0 0 0 0 -0 0</pose>
          <geometry>
            <mesh>
              <scale>1 1 1</scale>
              <uri>/home/lasitha/Documents/ROS_ws/kuka_sim_ws/src/kuka-iiwa/iiwa_description/meshes/iiwa14/visual/link_7.stl</uri>
            </mesh>
          </geometry>
          <material>
            <script>
              <name>Gazebo/Grey</name>
              <uri>file://media/materials/scripts/gazebo.material</uri>
            </script>
          </material>
        </visual>
        <gravity>1</gravity>
        <velocity_decay/>
        <self_collide>0</self_collide>
        <kinematic>0</kinematic>
      </link>
      <joint name='iiwa_joint_7' type='revolute'>
        <child>iiwa_link_7</child>
        <parent>iiwa_link_6</parent>
        <axis>
          <xyz>0 0 -1</xyz>
          <limit>
            <lower>-3.05433</lower>
            <upper>3.05433</upper>
            <effort>5000</effort>
            <velocity>100</velocity>
          </limit>
          <dynamics>
            <damping>0.4</damping>
            <friction>0.4</friction>
            <spring_reference>0</spring_reference>
            <spring_stiffness>0</spring_stiffness>
          </dynamics>
          <use_parent_model_frame>1</use_parent_model_frame>
        </axis>
        <physics>
          <provide_feedback>1</provide_feedback>
          <ode>
            <provide_feedback>1</provide_feedback>
            <limit>
              <cfm>0</cfm>
              <erp>0.2</erp>
            </limit>
          </ode>
        </physics>
      </joint>
      <link name='base_link'>
        <pose frame=''>1.5 0.25 0.594 -1e-06 -0 -0</pose>
        <inertial>
          <pose frame=''>-0.074619 -0 -0.08548 0 -0 0</pose>
          <mass>81.6138</mass>
          <inertia>
            <ixx>0</ixx>
            <ixy>0</ixy>
            <ixz>0</ixz>
            <iyy>0</iyy>
            <iyz>0</iyz>
            <izz>0</izz>
          </inertia>
        </inertial>
        <collision name='base_link_collision'>
          <pose frame=''>0 0 0 0 -0 0</pose>
          <geometry>
            <mesh>
              <scale>1 1 1</scale>
              <uri>/home/lasitha/Documents/ROS_ws/kuka_sim_ws/src/kuka-iiwa/iiwa_description/meshes/iiwa14/collision/Dual_Arm/base_link.STL</uri>
            </mesh>
          </geometry>
          <surface>
            <contact>
              <ode/>
            </contact>
            <friction>
              <ode>
                <mu>0.2</mu>
                <mu2>0.2</mu2>
              </ode>
              <torsional>
                <ode/>
              </torsional>
            </friction>
            <bounce/>
          </surface>
          <max_contacts>10</max_contacts>
        </collision>
        <visual name='base_link_visual'>
          <pose frame=''>0 0 0 0 -0 0</pose>
          <geometry>
            <mesh>
              <scale>1 1 1</scale>
              <uri>/home/lasitha/Documents/ROS_ws/kuka_sim_ws/src/kuka-iiwa/iiwa_description/meshes/iiwa14/collision/Dual_Arm/base_link.STL</uri>
            </mesh>
          </geometry>
          <material>
            <script>
              <name>Gazebo/Grey</name>
              <uri>file://media/materials/scripts/gazebo.material</uri>
            </script>
          </material>
        </visual>
        <gravity>1</gravity>
        <velocity_decay/>
        <self_collide>0</self_collide>
        <kinematic>0</kinematic>
      </link>
      <joint name='dual_arm_base_joint' type='revolute'>
        <child>base_link</child>
        <parent>iiwa_link_7</parent>
        <axis>
          <xyz>0 1e-06 1</xyz>
          <limit>
            <lower>-3.14</lower>
            <upper>3.14</upper>
            <effort>20000</effort>
            <velocity>13</velocity>
          </limit>
          <dynamics>
            <damping>0.005</damping>
            <friction>0.005</friction>
            <spring_reference>0</spring_reference>
            <spring_stiffness>0</spring_stiffness>
          </dynamics>
          <use_parent_model_frame>1</use_parent_model_frame>
        </axis>
      </joint>
      <link name='Link1'>
        <pose frame=''>1.42556 0.402871 0.483564 -1.43251 -0.775713 2.94539</pose>
        <inertial>
          <pose frame=''>0.003025 0.001485 -0.019671 0 -0 0</pose>
          <mass>0.323171</mass>
          <inertia>
            <ixx>9.86316e-05</ixx>
            <ixy>-1.83713e-06</ixy>
            <ixz>1.50311e-05</ixz>
            <iyy>0.000101227</iyy>
            <iyz>6.90483e-06</iyz>
            <izz>4.61899e-06</izz>
          </inertia>
        </inertial>
        <collision name='Link1_collision'>
          <pose frame=''>0 0 0 0 -0 0</pose>
          <geometry>
            <mesh>
              <scale>1 1 1</scale>
              <uri>/home/lasitha/Documents/ROS_ws/kuka_sim_ws/src/kuka-iiwa/iiwa_description/meshes/iiwa14/collision/Dual_Arm/Link1.STL</uri>
            </mesh>
          </geometry>
          <surface>
            <contact>
              <ode/>
            </contact>
            <friction>
              <ode>
                <mu>0.2</mu>
                <mu2>0.2</mu2>
              </ode>
              <torsional>
                <ode/>
              </torsional>
            </friction>
            <bounce/>
          </surface>
          <max_contacts>10</max_contacts>
        </collision>
        <visual name='Link1_visual'>
          <pose frame=''>0 0 0 0 -0 0</pose>
          <geometry>
            <mesh>
              <scale>1 1 1</scale>
              <uri>/home/lasitha/Documents/ROS_ws/kuka_sim_ws/src/kuka-iiwa/iiwa_description/meshes/iiwa14/collision/Dual_Arm/Link1.STL</uri>
            </mesh>
          </geometry>
          <material>
            <script>
              <name>Gazebo/White</name>
              <uri>file://media/materials/scripts/gazebo.material</uri>
            </script>
          </material>
        </visual>
        <gravity>1</gravity>
        <velocity_decay/>
        <self_collide>0</self_collide>
        <kinematic>0</kinematic>
      </link>
      <joint name='J_1' type='revolute'>
        <child>Link1</child>
        <parent>base_link</parent>
        <axis>
          <xyz>-0.09841 -0.990268 0.098411</xyz>
          <limit>
            <lower>-3.14</lower>
            <upper>3.14</upper>
            <effort>20000</effort>
            <velocity>13</velocity>
          </limit>
          <dynamics>
            <damping>0.005</damping>
            <friction>0.005</friction>
            <spring_reference>0</spring_reference>
            <spring_stiffness>0</spring_stiffness>
          </dynamics>
          <use_parent_model_frame>1</use_parent_model_frame>
        </axis>
      </joint>
      <link name='Link2'>
        <pose frame=''>1.4318 0.465753 0.477315 -0.08255 -0.465982 -2.86393</pose>
        <inertial>
          <pose frame=''>-0.084182 -9.9e-05 0.001198 0 -0 0</pose>
          <mass>0.161074</mass>
          <inertia>
            <ixx>1.38598e-06</ixx>
            <ixy>-3.7618e-07</ixy>
            <ixz>5.01831e-09</ixz>
            <iyy>0.000417336</iyy>
            <iyz>3.07943e-09</iyz>
            <izz>0.00041724</izz>
          </inertia>
        </inertial>
        <collision name='Link2_collision'>
          <pose frame=''>0 0 0 0 -0 0</pose>
          <geometry>
            <mesh>
              <scale>1 1 1</scale>
              <uri>/home/lasitha/Documents/ROS_ws/kuka_sim_ws/src/kuka-iiwa/iiwa_description/meshes/iiwa14/collision/Dual_Arm/Link2.STL</uri>
            </mesh>
          </geometry>
          <surface>
            <contact>
              <ode/>
            </contact>
            <friction>
              <ode>
                <mu>0.2</mu>
                <mu2>0.2</mu2>
              </ode>
              <torsional>
                <ode/>
              </torsional>
            </friction>
            <bounce/>
          </surface>
          <max_contacts>10</max_contacts>
        </collision>
        <visual name='Link2_visual'>
          <pose frame=''>0 0 0 0 -0 0</pose>
          <geometry>
            <mesh>
              <scale>1 1 1</scale>
              <uri>/home/lasitha/Documents/ROS_ws/kuka_sim_ws/src/kuka-iiwa/iiwa_description/meshes/iiwa14/collision/Dual_Arm/Link2.STL</uri>
            </mesh>
          </geometry>
          <material>
            <script>
              <name>Gazebo/Red</name>
              <uri>file://media/materials/scripts/gazebo.material</uri>
            </script>
          </material>
        </visual>
        <gravity>1</gravity>
        <velocity_decay/>
        <self_collide>0</self_collide>
        <kinematic>0</kinematic>
      </link>
      <joint name='J_2' type='revolute'>
        <child>Link2</child>
        <parent>Link1</parent>
        <axis>
          <xyz>0.453222 0.04344 0.890339</xyz>
          <limit>
            <lower>-3.14</lower>
            <upper>3.14</upper>
            <effort>20000</effort>
            <velocity>13</velocity>
          </limit>
          <dynamics>
            <damping>0.005</damping>
            <friction>0.005</friction>
            <spring_reference>0</spring_reference>
            <spring_stiffness>0</spring_stiffness>
          </dynamics>
          <use_parent_model_frame>1</use_parent_model_frame>
        </axis>
      </joint>
      <link name='Link3'>
        <pose frame=''>1.5853 0.509634 0.39704 -2.03797 0.068847 -1.32782</pose>
        <inertial>
          <pose frame=''>0.002897 0.001123 0.029006 0 -0 0</pose>
          <mass>0.117747</mass>
          <inertia>
            <ixx>9.95074e-05</ixx>
            <ixy>-2.66747e-07</ixy>
            <ixz>-3.1207e-06</ixz>
            <iyy>0.000106289</iyy>
            <iyz>-2.88857e-06</iyz>
            <izz>6.98821e-06</izz>
          </inertia>
        </inertial>
        <collision name='Link3_collision'>
          <pose frame=''>0 0 0 0 -0 0</pose>
          <geometry>
            <mesh>
              <scale>1 1 1</scale>
              <uri>/home/lasitha/Documents/ROS_ws/kuka_sim_ws/src/kuka-iiwa/iiwa_description/meshes/iiwa14/collision/Dual_Arm/Link3.STL</uri>
            </mesh>
          </geometry>
          <surface>
            <contact>
              <ode/>
            </contact>
            <friction>
              <ode>
                <mu>0.2</mu>
                <mu2>0.2</mu2>
              </ode>
              <torsional>
                <ode/>
              </torsional>
            </friction>
            <bounce/>
          </surface>
          <max_contacts>10</max_contacts>
        </collision>
        <visual name='Link3_visual'>
          <pose frame=''>0 0 0 0 -0 0</pose>
          <geometry>
            <mesh>
              <scale>1 1 1</scale>
              <uri>/home/lasitha/Documents/ROS_ws/kuka_sim_ws/src/kuka-iiwa/iiwa_description/meshes/iiwa14/collision/Dual_Arm/Link3.STL</uri>
            </mesh>
          </geometry>
          <material>
            <script>
              <name>Gazebo/White</name>
              <uri>file://media/materials/scripts/gazebo.material</uri>
            </script>
          </material>
        </visual>
        <gravity>1</gravity>
        <velocity_decay/>
        <self_collide>0</self_collide>
        <kinematic>0</kinematic>
      </link>
      <joint name='J_3' type='revolute'>
        <child>Link3</child>
        <parent>Link2</parent>
        <axis>
          <xyz>0.859163 0.244885 -0.4493</xyz>
          <limit>
            <lower>-3.14</lower>
            <upper>3.14</upper>
            <effort>20000</effort>
            <velocity>13</velocity>
          </limit>
          <dynamics>
            <damping>0.005</damping>
            <friction>0.005</friction>
            <spring_reference>0</spring_reference>
            <spring_stiffness>0</spring_stiffness>
          </dynamics>
          <use_parent_model_frame>1</use_parent_model_frame>
        </axis>
      </joint>
      <link name='Link4'>
        <pose frame=''>1.64321 0.498644 0.366119 1.64241 -0.278754 0.223241</pose>
        <inertial>
          <pose frame=''>-0.00107 -0.071398 -0.00107 0 -0 0</pose>
          <mass>0.117747</mass>
          <inertia>
            <ixx>9.95074e-05</ixx>
            <ixy>-2.66747e-07</ixy>
            <ixz>-3.1207e-06</ixz>
            <iyy>0.000106289</iyy>
            <iyz>-2.88857e-06</iyz>
            <izz>6.98821e-06</izz>
          </inertia>
        </inertial>
        <collision name='Link4_collision'>
          <pose frame=''>0 0 0 0 -0 0</pose>
          <geometry>
            <mesh>
              <scale>1 1 1</scale>
              <uri>/home/lasitha/Documents/ROS_ws/kuka_sim_ws/src/kuka-iiwa/iiwa_description/meshes/iiwa14/collision/Dual_Arm/Link4.STL</uri>
            </mesh>
          </geometry>
          <surface>
            <contact>
              <ode/>
            </contact>
            <friction>
              <ode>
                <mu>0.2</mu>
                <mu2>0.2</mu2>
              </ode>
              <torsional>
                <ode/>
              </torsional>
            </friction>
            <bounce/>
          </surface>
          <max_contacts>10</max_contacts>
        </collision>
        <visual name='Link4_visual'>
          <pose frame=''>0 0 0 0 -0 0</pose>
          <geometry>
            <mesh>
              <scale>1 1 1</scale>
              <uri>/home/lasitha/Documents/ROS_ws/kuka_sim_ws/src/kuka-iiwa/iiwa_description/meshes/iiwa14/collision/Dual_Arm/Link4.STL</uri>
            </mesh>
          </geometry>
          <material>
            <script>
              <name>Gazebo/Red</name>
              <uri>file://media/materials/scripts/gazebo.material</uri>
            </script>
          </material>
        </visual>
        <gravity>1</gravity>
        <velocity_decay/>
        <self_collide>0</self_collide>
        <kinematic>0</kinematic>
      </link>
      <joint name='J_4' type='revolute'>
        <child>Link4</child>
        <parent>Link3</parent>
        <axis>
          <xyz>0.240024 -0.968326 -0.068793</xyz>
          <limit>
            <lower>-3.14</lower>
            <upper>3.14</upper>
            <effort>20000</effort>
            <velocity>13</velocity>
          </limit>
          <dynamics>
            <damping>0.005</damping>
            <friction>0.005</friction>
            <spring_reference>0</spring_reference>
            <spring_stiffness>0</spring_stiffness>
          </dynamics>
          <use_parent_model_frame>1</use_parent_model_frame>
        </axis>
      </joint>
      <link name='gripper_base_link'>
        <pose frame=''>1.6835 0.519531 0.212689 -3.06998 -0.278754 0.223241</pose>
        <inertial>
          <pose frame=''>0 0 0.00892 0 -0 0</pose>
          <mass>1</mass>
          <inertia>
            <ixx>3.391e-05</ixx>
            <ixy>0</ixy>
            <ixz>0</ixz>
            <iyy>3.391e-05</iyy>
            <iyz>0</iyz>
            <izz>3.391e-05</izz>
          </inertia>
        </inertial>
        <collision name='gripper_base_link_collision'>
          <pose frame=''>0 0 0 0 -0 0</pose>
          <geometry>
            <mesh>
              <scale>1 1 1</scale>
              <uri>/home/lasitha/Documents/ROS_ws/kuka_sim_ws/src/kuka-iiwa/iiwa_description/meshes/iiwa14/collision/gripper_base.STL</uri>
            </mesh>
          </geometry>
          <surface>
            <contact>
              <ode/>
            </contact>
            <friction>
              <ode>
                <mu>0.2</mu>
                <mu2>0.2</mu2>
              </ode>
              <torsional>
                <ode/>
              </torsional>
            </friction>
            <bounce/>
          </surface>
          <max_contacts>10</max_contacts>
        </collision>
        <visual name='gripper_base_link_visual'>
          <pose frame=''>0 0 0 0 -0 0</pose>
          <geometry>
            <mesh>
              <scale>1 1 1</scale>
              <uri>/home/lasitha/Documents/ROS_ws/kuka_sim_ws/src/kuka-iiwa/iiwa_description/meshes/iiwa14/collision/gripper_base.STL</uri>
            </mesh>
          </geometry>
          <material>
            <script>
              <name>Gazebo/White</name>
              <uri>file://media/materials/scripts/gazebo.material</uri>
            </script>
          </material>
        </visual>
        <gravity>1</gravity>
        <velocity_decay/>
        <self_collide>0</self_collide>
        <kinematic>0</kinematic>
      </link>
      <joint name='gripper_base_joint' type='revolute'>
        <child>gripper_base_link</child>
        <parent>Link4</parent>
        <axis>
          <xyz>0.251801 0.13054 -0.958935</xyz>
          <limit>
            <lower>-3.14</lower>
            <upper>3.14</upper>
            <effort>20000</effort>
            <velocity>13</velocity>
          </limit>
          <dynamics>
            <damping>0.0001</damping>
            <friction>0.0001</friction>
            <spring_reference>0</spring_reference>
            <spring_stiffness>0</spring_stiffness>
          </dynamics>
          <use_parent_model_frame>1</use_parent_model_frame>
        </axis>
      </joint>
      <link name='claw_1_link'>
        <pose frame=''>1.68316 0.540979 0.197269 -2.86273 -0.027289 -1.35537</pose>
        <inertial>
          <pose frame=''>-0.02212 0 0.0052 0 -0 0</pose>
          <mass>0.00848</mass>
          <inertia>
            <ixx>3.2e-07</ixx>
            <ixy>0</ixy>
            <ixz>0</ixz>
            <iyy>1.89e-06</iyy>
            <iyz>0</iyz>
            <izz>1.6e-06</izz>
          </inertia>
        </inertial>
        <collision name='claw_1_link_collision'>
          <pose frame=''>0 0 0 0 -0 0</pose>
          <geometry>
            <mesh>
              <scale>1 1 1</scale>
              <uri>/home/lasitha/Documents/ROS_ws/kuka_sim_ws/src/kuka-iiwa/iiwa_description/meshes/iiwa14/collision/gripper_claw.STL</uri>
            </mesh>
          </geometry>
          <surface>
            <contact>
              <ode/>
            </contact>
            <friction>
              <ode>
                <mu>1</mu>
                <mu2>1</mu2>
              </ode>
              <torsional>
                <ode/>
              </torsional>
            </friction>
            <bounce/>
          </surface>
          <max_contacts>10</max_contacts>
        </collision>
        <visual name='claw_1_link_visual'>
          <pose frame=''>0 0 0 0 -0 0</pose>
          <geometry>
            <mesh>
              <scale>1 1 1</scale>
              <uri>/home/lasitha/Documents/ROS_ws/kuka_sim_ws/src/kuka-iiwa/iiwa_description/meshes/iiwa14/collision/gripper_claw.STL</uri>
            </mesh>
          </geometry>
          <material>
            <script>
              <name>Gazebo/Red</name>
              <uri>file://media/materials/scripts/gazebo.material</uri>
            </script>
          </material>
        </visual>
        <gravity>1</gravity>
        <velocity_decay/>
        <self_collide>0</self_collide>
        <kinematic>0</kinematic>
      </link>
      <joint name='claw_1_joint' type='revolute'>
        <child>claw_1_link</child>
        <parent>gripper_base_link</parent>
        <axis>
          <xyz>-0.937542 -0.212846 -0.275158</xyz>
          <limit>
            <lower>-1.57</lower>
            <upper>1.57</upper>
            <effort>20000</effort>
            <velocity>13</velocity>
          </limit>
          <dynamics>
            <damping>0.0001</damping>
            <friction>0.0001</friction>
            <spring_reference>0</spring_reference>
            <spring_stiffness>0</spring_stiffness>
          </dynamics>
          <use_parent_model_frame>1</use_parent_model_frame>
        </axis>
      </joint>
      <link name='claw_2_link'>
        <pose frame=''>1.69266 0.502652 0.194546 2.8589 -0.164929 1.84169</pose>
        <inertial>
          <pose frame=''>-0.02212 0 0.0052 0 -0 0</pose>
          <mass>0.00848</mass>
          <inertia>
            <ixx>3.2e-07</ixx>
            <ixy>0</ixy>
            <ixz>0</ixz>
            <iyy>1.89e-06</iyy>
            <iyz>0</iyz>
            <izz>1.6e-06</izz>
          </inertia>
        </inertial>
        <collision name='claw_2_link_collision'>
          <pose frame=''>0 0 0 0 -0 0</pose>
          <geometry>
            <mesh>
              <scale>1 1 1</scale>
              <uri>/home/lasitha/Documents/ROS_ws/kuka_sim_ws/src/kuka-iiwa/iiwa_description/meshes/iiwa14/collision/gripper_claw.STL</uri>
            </mesh>
          </geometry>
          <surface>
            <contact>
              <ode/>
            </contact>
            <friction>
              <ode>
                <mu>1</mu>
                <mu2>1</mu2>
              </ode>
              <torsional>
                <ode/>
              </torsional>
            </friction>
            <bounce/>
          </surface>
          <max_contacts>10</max_contacts>
        </collision>
        <visual name='claw_2_link_visual'>
          <pose frame=''>0 0 0 0 -0 0</pose>
          <geometry>
            <mesh>
              <scale>1 1 1</scale>
              <uri>/home/lasitha/Documents/ROS_ws/kuka_sim_ws/src/kuka-iiwa/iiwa_description/meshes/iiwa14/collision/gripper_claw.STL</uri>
            </mesh>
          </geometry>
          <material>
            <script>
              <name>Gazebo/Red</name>
              <uri>file://media/materials/scripts/gazebo.material</uri>
            </script>
          </material>
        </visual>
        <gravity>1</gravity>
        <velocity_decay/>
        <self_collide>0</self_collide>
        <kinematic>0</kinematic>
      </link>
      <joint name='claw_2_joint' type='revolute'>
        <child>claw_2_link</child>
        <parent>gripper_base_link</parent>
        <axis>
          <xyz>0.937542 0.212845 0.275158</xyz>
          <limit>
            <lower>-1.57</lower>
            <upper>1.57</upper>
            <effort>20000</effort>
            <velocity>13</velocity>
          </limit>
          <dynamics>
            <damping>0.0001</damping>
            <friction>0.0001</friction>
            <spring_reference>0</spring_reference>
            <spring_stiffness>0</spring_stiffness>
          </dynamics>
          <use_parent_model_frame>1</use_parent_model_frame>
        </axis>
      </joint>
      <link name='L2_1'>
        <pose frame=''>1.42556 0.097129 0.483565 1.43251 -0.775713 -2.9454</pose>
        <inertial>
          <pose frame=''>0.003025 0.001485 -0.019671 0 -0 0</pose>
          <mass>0.323171</mass>
          <inertia>
            <ixx>9.86316e-05</ixx>
            <ixy>-1.83713e-06</ixy>
            <ixz>1.50311e-05</ixz>
            <iyy>0.000101227</iyy>
            <iyz>6.90483e-06</iyz>
            <izz>4.61899e-06</izz>
          </inertia>
        </inertial>
        <collision name='L2_1_collision'>
          <pose frame=''>0 0 0 0 -0 0</pose>
          <geometry>
            <mesh>
              <scale>1 1 1</scale>
              <uri>/home/lasitha/Documents/ROS_ws/kuka_sim_ws/src/kuka-iiwa/iiwa_description/meshes/iiwa14/collision/Dual_Arm/Link1.STL</uri>
            </mesh>
          </geometry>
          <surface>
            <contact>
              <ode/>
            </contact>
            <friction>
              <ode>
                <mu>0.2</mu>
                <mu2>0.2</mu2>
              </ode>
              <torsional>
                <ode/>
              </torsional>
            </friction>
            <bounce/>
          </surface>
          <max_contacts>10</max_contacts>
        </collision>
        <visual name='L2_1_visual'>
          <pose frame=''>0 0 0 0 -0 0</pose>
          <geometry>
            <mesh>
              <scale>1 1 1</scale>
              <uri>/home/lasitha/Documents/ROS_ws/kuka_sim_ws/src/kuka-iiwa/iiwa_description/meshes/iiwa14/collision/Dual_Arm/Link1.STL</uri>
            </mesh>
          </geometry>
          <material>
            <script>
              <name>Gazebo/White</name>
              <uri>file://media/materials/scripts/gazebo.material</uri>
            </script>
          </material>
        </visual>
        <gravity>1</gravity>
        <velocity_decay/>
        <self_collide>0</self_collide>
        <kinematic>0</kinematic>
      </link>
      <joint name='J_21' type='revolute'>
        <child>L2_1</child>
        <parent>base_link</parent>
        <axis>
          <xyz>-0.09841 0.990268 0.09841</xyz>
          <limit>
            <lower>-3.14</lower>
            <upper>3.14</upper>
            <effort>20000</effort>
            <velocity>13</velocity>
          </limit>
          <dynamics>
            <damping>0.005</damping>
            <friction>0.005</friction>
            <spring_reference>0</spring_reference>
            <spring_stiffness>0</spring_stiffness>
          </dynamics>
          <use_parent_model_frame>1</use_parent_model_frame>
        </axis>
      </joint>
      <link name='L2_2'>
        <pose frame=''>1.4318 0.034247 0.477316 -2.65883 -1.03363 2.64257</pose>
        <inertial>
          <pose frame=''>-0.084182 -9.9e-05 0.001198 0 -0 0</pose>
          <mass>0.161074</mass>
          <inertia>
            <ixx>1.38598e-06</ixx>
            <ixy>-3.7618e-07</ixy>
            <ixz>5.01831e-09</ixz>
            <iyy>0.000417336</iyy>
            <iyz>3.07943e-09</iyz>
            <izz>0.00041724</izz>
          </inertia>
        </inertial>
        <collision name='L2_2_collision'>
          <pose frame=''>0 0 0 0 -0 0</pose>
          <geometry>
            <mesh>
              <scale>1 1 1</scale>
              <uri>/home/lasitha/Documents/ROS_ws/kuka_sim_ws/src/kuka-iiwa/iiwa_description/meshes/iiwa14/collision/Dual_Arm/Link2.STL</uri>
            </mesh>
          </geometry>
          <surface>
            <contact>
              <ode/>
            </contact>
            <friction>
              <ode>
                <mu>0.2</mu>
                <mu2>0.2</mu2>
              </ode>
              <torsional>
                <ode/>
              </torsional>
            </friction>
            <bounce/>
          </surface>
          <max_contacts>10</max_contacts>
        </collision>
        <visual name='L2_2_visual'>
          <pose frame=''>0 0 0 0 -0 0</pose>
          <geometry>
            <mesh>
              <scale>1 1 1</scale>
              <uri>/home/lasitha/Documents/ROS_ws/kuka_sim_ws/src/kuka-iiwa/iiwa_description/meshes/iiwa14/collision/Dual_Arm/Link2.STL</uri>
            </mesh>
          </geometry>
          <material>
            <script>
              <name>Gazebo/Red</name>
              <uri>file://media/materials/scripts/gazebo.material</uri>
            </script>
          </material>
        </visual>
        <gravity>1</gravity>
        <velocity_decay/>
        <self_collide>0</self_collide>
        <kinematic>0</kinematic>
      </link>
      <joint name='J_22' type='revolute'>
        <child>L2_2</child>
        <parent>L2_1</parent>
        <axis>
          <xyz>-0.890339 -0.04344 -0.453222</xyz>
          <limit>
            <lower>-3.14</lower>
            <upper>3.14</upper>
            <effort>20000</effort>
            <velocity>13</velocity>
          </limit>
          <dynamics>
            <damping>0.005</damping>
            <friction>0.005</friction>
            <spring_reference>0</spring_reference>
            <spring_stiffness>0</spring_stiffness>
          </dynamics>
          <use_parent_model_frame>1</use_parent_model_frame>
        </axis>
      </joint>
      <link name='L2_3'>
        <pose frame=''>1.51208 -0.009635 0.323823 2.65618 0.239841 1.49489</pose>
        <inertial>
          <pose frame=''>0.002897 0.001123 0.029006 0 -0 0</pose>
          <mass>0.117747</mass>
          <inertia>
            <ixx>9.95074e-05</ixx>
            <ixy>-2.66747e-07</ixy>
            <ixz>-3.1207e-06</ixz>
            <iyy>0.000106289</iyy>
            <iyz>-2.88857e-06</iyz>
            <izz>6.98821e-06</izz>
          </inertia>
        </inertial>
        <collision name='L2_3_collision'>
          <pose frame=''>0 0 0 0 -0 0</pose>
          <geometry>
            <mesh>
              <scale>1 1 1</scale>
              <uri>/home/lasitha/Documents/ROS_ws/kuka_sim_ws/src/kuka-iiwa/iiwa_description/meshes/iiwa14/collision/Dual_Arm/Link3.STL</uri>
            </mesh>
          </geometry>
          <surface>
            <contact>
              <ode/>
            </contact>
            <friction>
              <ode>
                <mu>0.2</mu>
                <mu2>0.2</mu2>
              </ode>
              <torsional>
                <ode/>
              </torsional>
            </friction>
            <bounce/>
          </surface>
          <max_contacts>10</max_contacts>
        </collision>
        <visual name='L2_3_visual'>
          <pose frame=''>0 0 0 0 -0 0</pose>
          <geometry>
            <mesh>
              <scale>1 1 1</scale>
              <uri>/home/lasitha/Documents/ROS_ws/kuka_sim_ws/src/kuka-iiwa/iiwa_description/meshes/iiwa14/collision/Dual_Arm/Link3.STL</uri>
            </mesh>
          </geometry>
          <material>
            <script>
              <name>Gazebo/White</name>
              <uri>file://media/materials/scripts/gazebo.material</uri>
            </script>
          </material>
        </visual>
        <gravity>1</gravity>
        <velocity_decay/>
        <self_collide>0</self_collide>
        <kinematic>0</kinematic>
      </link>
      <joint name='J_23' type='revolute'>
        <child>L2_3</child>
        <parent>L2_2</parent>
        <axis>
          <xyz>0.4493 -0.244885 -0.859163</xyz>
          <limit>
            <lower>-3.14</lower>
            <upper>3.14</upper>
            <effort>20000</effort>
            <velocity>13</velocity>
          </limit>
          <dynamics>
            <damping>0.005</damping>
            <friction>0.005</friction>
            <spring_reference>0</spring_reference>
            <spring_stiffness>0</spring_stiffness>
          </dynamics>
          <use_parent_model_frame>1</use_parent_model_frame>
        </axis>
      </joint>
      <link name='L2_4'>
        <pose frame=''>1.54313 0.001352 0.265976 2.32898 1.21805 -2.49097</pose>
        <inertial>
          <pose frame=''>-0.00107 -0.071398 -0.00107 0 -0 0</pose>
          <mass>0.117747</mass>
          <inertia>
            <ixx>9.95074e-05</ixx>
            <ixy>-2.66747e-07</ixy>
            <ixz>-3.1207e-06</ixz>
            <iyy>0.000106289</iyy>
            <iyz>-2.88857e-06</iyz>
            <izz>6.98821e-06</izz>
          </inertia>
        </inertial>
        <collision name='L2_4_collision'>
          <pose frame=''>0 0 0 0 -0 0</pose>
          <geometry>
            <mesh>
              <scale>1 1 1</scale>
              <uri>/home/lasitha/Documents/ROS_ws/kuka_sim_ws/src/kuka-iiwa/iiwa_description/meshes/iiwa14/collision/Dual_Arm/Link4.STL</uri>
            </mesh>
          </geometry>
          <surface>
            <contact>
              <ode/>
            </contact>
            <friction>
              <ode>
                <mu>0.2</mu>
                <mu2>0.2</mu2>
              </ode>
              <torsional>
                <ode/>
              </torsional>
            </friction>
            <bounce/>
          </surface>
          <max_contacts>10</max_contacts>
        </collision>
        <visual name='L2_4_visual'>
          <pose frame=''>0 0 0 0 -0 0</pose>
          <geometry>
            <mesh>
              <scale>1 1 1</scale>
              <uri>/home/lasitha/Documents/ROS_ws/kuka_sim_ws/src/kuka-iiwa/iiwa_description/meshes/iiwa14/collision/Dual_Arm/Link4.STL</uri>
            </mesh>
          </geometry>
          <material>
            <script>
              <name>Gazebo/Red</name>
              <uri>file://media/materials/scripts/gazebo.material</uri>
            </script>
          </material>
        </visual>
        <gravity>1</gravity>
        <velocity_decay/>
        <self_collide>0</self_collide>
        <kinematic>0</kinematic>
      </link>
      <joint name='J_24' type='revolute'>
        <child>L2_4</child>
        <parent>L2_3</parent>
        <axis>
          <xyz>0.073666 0.968578 -0.237549</xyz>
          <limit>
            <lower>-3.14</lower>
            <upper>3.14</upper>
            <effort>20000</effort>
            <velocity>13</velocity>
          </limit>
          <dynamics>
            <damping>0.005</damping>
            <friction>0.005</friction>
            <spring_reference>0</spring_reference>
            <spring_stiffness>0</spring_stiffness>
          </dynamics>
          <use_parent_model_frame>1</use_parent_model_frame>
        </axis>
      </joint>
      <link name='2_gripper_base_link'>
        <pose frame=''>1.69651 -0.020157 0.225842 -2.38341 1.21805 -2.49097</pose>
        <inertial>
          <pose frame=''>0 0 0.00892 0 -0 0</pose>
          <mass>1</mass>
          <inertia>
            <ixx>3.391e-05</ixx>
            <ixy>0</ixy>
            <ixz>0</ixz>
            <iyy>3.391e-05</iyy>
            <iyz>0</iyz>
            <izz>3.391e-05</izz>
          </inertia>
        </inertial>
        <collision name='2_gripper_base_link_collision'>
          <pose frame=''>0 0 0 0 -0 0</pose>
          <geometry>
            <mesh>
              <scale>1 1 1</scale>
              <uri>/home/lasitha/Documents/ROS_ws/kuka_sim_ws/src/kuka-iiwa/iiwa_description/meshes/iiwa14/collision/gripper_base.STL</uri>
            </mesh>
          </geometry>
          <surface>
            <contact>
              <ode/>
            </contact>
            <friction>
              <ode>
                <mu>0.2</mu>
                <mu2>0.2</mu2>
              </ode>
              <torsional>
                <ode/>
              </torsional>
            </friction>
            <bounce/>
          </surface>
          <max_contacts>10</max_contacts>
        </collision>
        <visual name='2_gripper_base_link_visual'>
          <pose frame=''>0 0 0 0 -0 0</pose>
          <geometry>
            <mesh>
              <scale>1 1 1</scale>
              <uri>/home/lasitha/Documents/ROS_ws/kuka_sim_ws/src/kuka-iiwa/iiwa_description/meshes/iiwa14/collision/gripper_base.STL</uri>
            </mesh>
          </geometry>
          <material>
            <script>
              <name>Gazebo/White</name>
              <uri>file://media/materials/scripts/gazebo.material</uri>
            </script>
          </material>
        </visual>
        <gravity>1</gravity>
        <velocity_decay/>
        <self_collide>0</self_collide>
        <kinematic>0</kinematic>
      </link>
      <joint name='2_gripper_base_joint' type='revolute'>
        <child>2_gripper_base_link</child>
        <parent>L2_4</parent>
        <axis>
          <xyz>0.958649 -0.13443 -0.250842</xyz>
          <limit>
            <lower>-1.57</lower>
            <upper>1.57</upper>
            <effort>20000</effort>
            <velocity>13</velocity>
          </limit>
          <dynamics>
            <damping>0.0001</damping>
            <friction>0.0001</friction>
            <spring_reference>0</spring_reference>
            <spring_stiffness>0</spring_stiffness>
          </dynamics>
          <use_parent_model_frame>1</use_parent_model_frame>
        </axis>
      </joint>
      <link name='2_claw_1_link'>
        <pose frame=''>1.71183 -0.041678 0.226153 1.85419 0.212925 1.59372</pose>
        <inertial>
          <pose frame=''>-0.02212 0 0.0052 0 -0 0</pose>
          <mass>0.00848</mass>
          <inertia>
            <ixx>3.2e-07</ixx>
            <ixy>0</ixy>
            <ixz>0</ixz>
            <iyy>1.89e-06</iyy>
            <iyz>0</iyz>
            <izz>1.6e-06</izz>
          </inertia>
        </inertial>
        <collision name='2_claw_1_link_collision'>
          <pose frame=''>0 0 0 0 -0 0</pose>
          <geometry>
            <mesh>
              <scale>1 1 1</scale>
              <uri>/home/lasitha/Documents/ROS_ws/kuka_sim_ws/src/kuka-iiwa/iiwa_description/meshes/iiwa14/collision/gripper_claw.STL</uri>
            </mesh>
          </geometry>
          <surface>
            <contact>
              <ode/>
            </contact>
            <friction>
              <ode>
                <mu>0.2</mu>
                <mu2>0.2</mu2>
              </ode>
              <torsional>
                <ode/>
              </torsional>
            </friction>
            <bounce/>
          </surface>
          <max_contacts>10</max_contacts>
        </collision>
        <visual name='2_claw_1_link_visual'>
          <pose frame=''>0 0 0 0 -0 0</pose>
          <geometry>
            <mesh>
              <scale>1 1 1</scale>
              <uri>/home/lasitha/Documents/ROS_ws/kuka_sim_ws/src/kuka-iiwa/iiwa_description/meshes/iiwa14/collision/gripper_claw.STL</uri>
            </mesh>
          </geometry>
          <material>
            <script>
              <name>Gazebo/Red</name>
              <uri>file://media/materials/scripts/gazebo.material</uri>
            </script>
          </material>
        </visual>
        <gravity>1</gravity>
        <velocity_decay/>
        <self_collide>0</self_collide>
        <kinematic>0</kinematic>
      </link>
      <joint name='2_claw_1_joint' type='revolute'>
        <child>2_claw_1_link</child>
        <parent>2_gripper_base_link</parent>
        <axis>
          <xyz>0.274893 0.209247 0.938429</xyz>
          <limit>
            <lower>-1.57</lower>
            <upper>1.57</upper>
            <effort>20000</effort>
            <velocity>13</velocity>
          </limit>
          <dynamics>
            <damping>0.0001</damping>
            <friction>0.0001</friction>
            <spring_reference>0</spring_reference>
            <spring_stiffness>0</spring_stiffness>
          </dynamics>
          <use_parent_model_frame>1</use_parent_model_frame>
        </axis>
      </joint>
      <link name='2_claw_2_link'>
        <pose frame=''>1.71475 -0.003341 0.216751 -1.807 -0.264476 -1.74679</pose>
        <inertial>
          <pose frame=''>-0.02212 0 0.0052 0 -0 0</pose>
          <mass>0.00848</mass>
          <inertia>
            <ixx>3.2e-07</ixx>
            <ixy>0</ixy>
            <ixz>0</ixz>
            <iyy>1.89e-06</iyy>
            <iyz>0</iyz>
            <izz>1.6e-06</izz>
          </inertia>
        </inertial>
        <collision name='2_claw_2_link_collision'>
          <pose frame=''>0 0 0 0 -0 0</pose>
          <geometry>
            <mesh>
              <scale>1 1 1</scale>
              <uri>/home/lasitha/Documents/ROS_ws/kuka_sim_ws/src/kuka-iiwa/iiwa_description/meshes/iiwa14/collision/gripper_claw.STL</uri>
            </mesh>
          </geometry>
          <surface>
            <contact>
              <ode/>
            </contact>
            <friction>
              <ode>
                <mu>0.2</mu>
                <mu2>0.2</mu2>
              </ode>
              <torsional>
                <ode/>
              </torsional>
            </friction>
            <bounce/>
          </surface>
          <max_contacts>10</max_contacts>
        </collision>
        <visual name='2_claw_2_link_visual'>
          <pose frame=''>0 0 0 0 -0 0</pose>
          <geometry>
            <mesh>
              <scale>1 1 1</scale>
              <uri>/home/lasitha/Documents/ROS_ws/kuka_sim_ws/src/kuka-iiwa/iiwa_description/meshes/iiwa14/collision/gripper_claw.STL</uri>
            </mesh>
          </geometry>
          <material>
            <script>
              <name>Gazebo/Red</name>
              <uri>file://media/materials/scripts/gazebo.material</uri>
            </script>
          </material>
        </visual>
        <gravity>1</gravity>
        <velocity_decay/>
        <self_collide>0</self_collide>
        <kinematic>0</kinematic>
      </link>
      <joint name='2_claw_2_joint' type='revolute'>
        <child>2_claw_2_link</child>
        <parent>2_gripper_base_link</parent>
        <axis>
          <xyz>-0.274893 -0.209247 -0.938429</xyz>
          <limit>
            <lower>-1.57</lower>
            <upper>1.57</upper>
            <effort>20000</effort>
            <velocity>13</velocity>
          </limit>
          <dynamics>
            <damping>0.0001</damping>
            <friction>0.0001</friction>
            <spring_reference>0</spring_reference>
            <spring_stiffness>0</spring_stiffness>
          </dynamics>
          <use_parent_model_frame>1</use_parent_model_frame>
        </axis>
      </joint>
      <plugin name='gazebo_ros_control' filename='libgazebo_ros_control.so'>
        <robotNamespace>/iiwa</robotNamespace>
      </plugin>
      <static>0</static>
      <pose frame=''>0 0 0 0 -0 0</pose>
    </model>
    <state world_name='default'>
      <sim_time>693 936000000</sim_time>
      <real_time>252 519108337</real_time>
      <wall_time>1556570544 151936161</wall_time>
      <iterations>244076</iterations>
      <model name='ground_plane'>
        <pose frame=''>0 0 0 0 -0 0</pose>
        <scale>1 1 1</scale>
        <link name='link'>
          <pose frame=''>0 0 0 0 -0 0</pose>
          <velocity>0 0 0 0 -0 0</velocity>
          <acceleration>0 0 0 0 -0 0</acceleration>
          <wrench>0 0 0 0 -0 0</wrench>
        </link>
      </model>
      <model name='iiwa14'>
        <pose frame=''>0 0 0 0 -0 0</pose>
        <scale>1 1 1</scale>
        <link name='2_claw_1_link'>
          <pose frame=''>1.68048 -0.004901 0.147861 1.87433 -0.752146 2.86193</pose>
          <velocity>-0.001584 -2.8e-05 -0.000808 0.003853 0.007818 -0.005412</velocity>
          <acceleration>-1.70757 -0.050844 -0.929964 1.40434 1.07145 0.896528</acceleration>
          <wrench>-0.01448 -0.000431 -0.007886 0 -0 0</wrench>
        </link>
        <link name='2_claw_2_link'>
          <pose frame=''>1.68064 0.034192 0.141674 -1.75867 -0.782369 -2.72791</pose>
          <velocity>-0.001564 -1.8e-05 -0.000505 0.006177 0.008039 -0.003185</velocity>
          <acceleration>-1.69025 0.032719 -0.62391 0.513004 -0.356605 2.61128</acceleration>
          <wrench>-0.014333 0.000277 -0.005291 0 -0 0</wrench>
        </link>
        <link name='2_gripper_base_link'>
          <pose frame=''>1.66822 0.016633 0.157008 -2.92201 0.770874 -2.99133</pose>
          <velocity>-0.001447 2.8e-05 -0.000506 0.007385 0.008612 -0.001044</velocity>
          <acceleration>-1.50166 0.067464 -0.568072 -2.04024 0.812662 2.09789</acceleration>
          <wrench>-1.50166 0.067464 -0.568072 0 -0 0</wrench>
        </link>
        <link name='L2_1'>
          <pose frame=''>1.42634 0.096901 0.483247 1.4385 -0.73123 -2.95059</pose>
          <velocity>9.5e-05 7e-06 0.000301 0.00373 -0.069664 0.001535</velocity>
          <acceleration>0.043251 0.003625 0.281564 -2.02467 -0.848476 2.57818</acceleration>
          <wrench>0.013977 0.001171 0.090993 0 -0 0</wrench>
        </link>
        <link name='L2_2'>
          <pose frame=''>1.43284 0.034041 0.477003 -2.91694 -1.04088 2.9293</pose>
          <velocity>-0.00018 1.4e-05 0.000258 -0.003227 -0.004887 -0.000709</velocity>
          <acceleration>0.17155 -0.250998 0.485252 2.88481 -1.55263 3.10481</acceleration>
          <wrench>0.027632 -0.040429 0.078161 0 -0 0</wrench>
        </link>
        <link name='L2_3'>
          <pose frame=''>1.52115 0.014874 0.322833 2.61624 0.072598 1.48311</pose>
          <velocity>0.000612 -0.00053 0.000811 -0.021097 -0.000781 0.029921</velocity>
          <acceleration>0.638982 -0.585101 0.82848 2.1986 0.980468 -1.62824</acceleration>
          <wrench>0.075238 -0.068894 0.097551 0 -0 0</wrench>
        </link>
        <link name='L2_4'>
          <pose frame=''>1.5558 0.034809 0.26941 1.67477 0.783465 3.12757</pose>
          <velocity>0.001021 -0.000615 0.00242 -0.016911 0.051607 0.022421</velocity>
          <acceleration>-1.3263 -0.315933 -0.03977 -2.87432 0.736121 0.735902</acceleration>
          <wrench>-0.156167 -0.0372 -0.004683 0 -0 0</wrench>
        </link>
        <link name='Link1'>
          <pose frame=''>1.42537 0.402643 0.483267 -1.37173 -1.04914 2.8723</pose>
          <velocity>0.000141 8e-06 0.000292 0.000355 0.005688 -0.000194</velocity>
          <acceleration>0.144297 0.00867 0.303646 0.803988 -0.971643 2.11412</acceleration>
          <wrench>0.046633 0.002802 0.09813 0 -0 0</wrench>
        </link>
        <link name='Link2'>
          <pose frame=''>1.43143 0.465543 0.477013 -0.143805 -0.734358 -2.91758</pose>
          <velocity>0.00013 1.7e-05 0.000302 0.010487 0.006403 -0.010273</velocity>
          <acceleration>-0.082305 -0.034729 0.052991 1.23684 0.752758 -1.47095</acceleration>
          <wrench>-0.013257 -0.005594 0.008535 0 -0 0</wrench>
        </link>
        <link name='Link3'>
          <pose frame=''>1.56075 0.495131 0.357283 -2.30953 0.097943 -1.43556</pose>
          <velocity>-0.000329 -7.8e-05 -0.000218 0.001429 0.004397 -0.001661</velocity>
          <acceleration>-0.416167 -0.083126 -0.306149 -0.355468 0.801366 -0.265078</acceleration>
          <wrench>-0.049002 -0.009788 -0.036048 0 -0 0</wrench>
        </link>
        <link name='Link4'>
          <pose frame=''>1.60732 0.478877 0.312467 1.67713 -0.403868 0.093313</pose>
          <velocity>-0.000592 -0.000104 -0.000481 0.001441 0.002786 -0.001643</velocity>
          <acceleration>-0.756719 -0.05229 -0.537788 3.13548 0.227275 -1.44672</acceleration>
          <wrench>-0.089101 -0.006157 -0.063323 0 -0 0</wrench>
        </link>
        <link name='base_link'>
          <pose frame=''>1.50005 0.250003 0.593861 3.1e-05 -0.002147 0.003165</pose>
          <velocity>0.000557 -2e-06 -0 7.3e-05 0.003773 -1.5e-05</velocity>
          <acceleration>0 0 0 0 -0 0</acceleration>
          <wrench>19.0936 0.45639 22.9022 0 -0 0</wrench>
        </link>
        <link name='claw_1_link'>
          <pose frame=''>1.67148 0.523568 0.151818 -2.11689 -1.08754 -2.40007</pose>
          <velocity>-0.001085 2e-06 -0.000635 0.0014 0.002857 -0.000661</velocity>
          <acceleration>-1.14318 0.025719 -0.657778 2.60665 -0.731591 -0.56913</acceleration>
          <wrench>-0.009694 0.000218 -0.005578 0 -0 0</wrench>
        </link>
        <link name='claw_2_link'>
          <pose frame=''>1.67835 0.484718 0.148631 1.99198 -1.12059 2.81993</pose>
          <velocity>-0.001113 2.6e-05 -0.000686 0.000732 0.003208 -0.000924</velocity>
          <acceleration>-1.17828 0.032938 -0.712495 -2.41789 -0.438727 0.866676</acceleration>
          <wrench>-0.009992 0.000279 -0.006042 0 -0 0</wrench>
        </link>
        <link name='frame'>
          <pose frame=''>0 0 0 0 -0 0</pose>
          <velocity>0 0 0 0 -0 0</velocity>
          <acceleration>0 0 0 0 -0 0</acceleration>
          <wrench>0 0 -0 0 -0 0</wrench>
        </link>
        <link name='gripper_base_link'>
          <pose frame=''>1.66828 0.501658 0.166229 -3.05376 -0.408236 0.140068</pose>
          <velocity>-0.001061 -2e-06 -0.000648 0.001099 0.002932 -0.000844</velocity>
          <acceleration>-1.08349 0.004554 -0.656853 -2.04213 0.209662 2.29723</acceleration>
          <wrench>-1.08349 0.004554 -0.656853 0 -0 0</wrench>
        </link>
        <link name='iiwa_link_0'>
          <pose frame=''>1.5 0.25 1.9 3.14159 -1.1e-05 0</pose>
          <velocity>-0 0 0 0 -0 0</velocity>
          <acceleration>3.4e-05 0.000112 9.6e-05 0.004989 -0.001882 0.003043</acceleration>
          <wrench>0.000171 0.000562 0.000479 0 -0 0</wrench>
        </link>
        <link name='iiwa_link_1'>
          <pose frame=''>1.5 0.250002 1.74249 3.14159 4.7e-05 2.8e-05</pose>
          <velocity>0 0 0 0 0 -1.2e-05</velocity>
          <acceleration>0.000324 1.9e-05 -3e-06 -0.000149 0.000443 -0.011886</acceleration>
          <wrench>0.001297 7.6e-05 -1.3e-05 0 -0 0</wrench>
        </link>
        <link name='iiwa_link_2'>
          <pose frame=''>1.49999 0.249999 1.53999 -1.57081 -4.9e-05 -3.14157</pose>
          <velocity>-0 -0 0 0 -0.000874 -1.3e-05</velocity>
          <acceleration>0.050785 -3.6e-05 -0.000229 -0.000164 -0.357659 -0.03203</acceleration>
          <wrench>0.203138 -0.000144 -0.000918 0 -0 0</wrench>
        </link>
        <link name='iiwa_link_3'>
          <pose frame=''>1.49999 0.25 1.33548 3.14157 2.4e-05 2e-06</pose>
          <velocity>0.000178 -0 0 -1e-06 -0.000873 0.000716</velocity>
          <acceleration>0.313326 -0.00024 4.4e-05 -0.000828 -0.873363 0.716257</acceleration>
          <wrench>0.939979 -0.000721 0.000133 0 -0 0</wrench>
        </link>
        <link name='iiwa_link_4'>
          <pose frame=''>1.49999 0.249998 1.11997 -1.57084 1.2e-05 7e-06</pose>
          <velocity>0.000367 -0 -0 -1e-06 -0.001685 0.000714</velocity>
          <acceleration>0.455254 -0.000433 -6.7e-05 -0.001016 -0.580969 2.07065</acceleration>
          <wrench>1.22919 -0.001168 -0.000182 0 -0 0</wrench>
        </link>
        <link name='iiwa_link_5'>
          <pose frame=''>1.5 0.249995 0.935467 3.14159 2.1e-05 -3.14156</pose>
          <velocity>0.000678 -1e-06 0 -2e-06 -0.001684 -9.4e-05</velocity>
          <acceleration>0.8077 -0.0007 -0.000187 3.13976 -1.45737 3.04758</acceleration>
          <wrench>1.37309 -0.001189 -0.000318 0 -0 0</wrench>
        </link>
        <link name='iiwa_link_6'>
          <pose frame=''>1.5 0.249997 0.719953 -1.57085 1.7e-05 -3.14156</pose>
          <velocity>0.00104 -1e-06 0 -5e-06 0.003836 -0.0001</velocity>
          <acceleration>1.03802 -0.001301 4.6e-05 3.13648 0.203174 3.01145</acceleration>
          <wrench>1.86844 -0.002342 8.2e-05 0 -0 0</wrench>
        </link>
        <link name='iiwa_link_7'>
          <pose frame=''>1.50006 0.250001 0.638967 -3.14154 0.000204 0.000188</pose>
          <velocity>0.000731 0 -0 -2.1e-05 0.003846 -7.6e-05</velocity>
          <acceleration>0.654279 -1e-06 -0.000177 3.12088 -0.704024 3.06556</acceleration>
          <wrench>0.196284 -0 -5.3e-05 0 -0 0</wrench>
        </link>
        <link name='surface'>
          <pose frame=''>1.5 0.25 -3.8e-05 3.4e-05 6.1e-05 1.57069</pose>
          <velocity>3e-06 6e-06 0.000255 -0.005997 0.001896 -9e-06</velocity>
          <acceleration>0.002387 0.029145 1.72195 -1.58352 1.35068 -3.13538</acceleration>
          <wrench>0.0087 0.106234 6.2765 0 -0 0</wrench>
        </link>
      </model>
      <model name='unit_box'>
        <pose frame=''>1.55177 0.242359 0.074212 -0.00147 -0.003293 1.5891</pose>
        <scale>0.894555 0.021043 0.088817</scale>
        <link name='link'>
          <pose frame=''>1.55177 0.242359 0.074212 -0.00147 -0.003293 1.5891</pose>
          <velocity>6.1e-05 0.000215 0.000358 -0.000671 1.3e-05 -2.6e-05</velocity>
          <acceleration>0.060563 0.215473 0.357938 -0.671437 0.013488 -0.025797</acceleration>
          <wrench>0.060563 0.215473 0.357938 0 -0 0</wrench>
        </link>
      </model>
      <light name='sun'>
        <pose frame=''>0 0 10 0 -0 0</pose>
      </light>
    </state>
    <gui fullscreen='0'>
      <camera name='user_camera'>
        <pose frame=''>2.08421 -1.95945 1.04588 0 0.297164 2.06334</pose>
        <view_controller>orbit</view_controller>
        <projection_type>perspective</projection_type>
      </camera>
    </gui>
    <model name='unit_box'>
      <pose frame=''>1.619 -1.0081 0.5 0 -0 0</pose>
      <link name='link'>
        <inertial>
          <mass>0.3</mass>
          <inertia>
            <ixx>0.166667</ixx>
            <ixy>0</ixy>
            <ixz>0</ixz>
            <iyy>0.166667</iyy>
            <iyz>0</iyz>
            <izz>0.166667</izz>
          </inertia>
        </inertial>
        <collision name='collision'>
          <geometry>
            <box>
              <size>0.999998 0.999991 0.999991</size>
            </box>
          </geometry>
          <max_contacts>10</max_contacts>
          <surface>
            <contact>
              <ode/>
            </contact>
            <bounce/>
            <friction>
              <torsional>
                <ode/>
              </torsional>
              <ode>
                <mu>1</mu>
                <mu2>1</mu2>
              </ode>
            </friction>
          </surface>
        </collision>
        <visual name='visual'>
          <geometry>
            <box>
              <size>0.999998 0.999991 0.999991</size>
            </box>
          </geometry>
          <material>
            <script>
              <name>Gazebo/Blue</name>
              <uri>file://media/materials/scripts/gazebo.material</uri>
            </script>
          </material>
        </visual>
        <self_collide>0</self_collide>
        <kinematic>0</kinematic>
      </link>
    </model>
  </world>
</sdf>
