<sdf version='1.6'>
  <world name='default'>
    <light name='sun' type='directional'>
      <cast_shadows>1</cast_shadows>
      <pose frame=''>0 0 10 0 -0 0</pose>
      <diffuse>0.8 0.8 0.8 1</diffuse>
      <specular>0.2 0.2 0.2 1</specular>
      <attenuation>
        <range>1000</range>
        <constant>0.9</constant>
        <linear>0.01</linear>
        <quadratic>0.001</quadratic>
      </attenuation>
      <direction>-0.5 0.1 -0.9</direction>
    </light>
    <model name='ground_plane'>
      <static>1</static>
      <link name='link'>
        <collision name='collision'>
          <geometry>
            <plane>
              <normal>0 0 1</normal>
              <size>100 100</size>
            </plane>
          </geometry>
          <surface>
            <friction>
              <ode>
                <mu>100</mu>
                <mu2>50</mu2>
              </ode>
              <torsional>
                <ode/>
              </torsional>
            </friction>
            <contact>
              <ode/>
            </contact>
            <bounce/>
          </surface>
          <max_contacts>10</max_contacts>
        </collision>
        <visual name='visual'>
          <cast_shadows>0</cast_shadows>
          <geometry>
            <plane>
              <normal>0 0 1</normal>
              <size>100 100</size>
            </plane>
          </geometry>
          <material>
            <script>
              <uri>file://media/materials/scripts/gazebo.material</uri>
              <name>Gazebo/Grey</name>
            </script>
          </material>
        </visual>
        <self_collide>0</self_collide>
        <kinematic>0</kinematic>
      </link>
    </model>
    <gravity>0 0 -9.8</gravity>
    <magnetic_field>6e-06 2.3e-05 -4.2e-05</magnetic_field>
    <atmosphere type='adiabatic'/>
    <physics name='default_physics' default='0' type='ode'>
      <max_step_size>0.001</max_step_size>
      <real_time_factor>1</real_time_factor>
      <real_time_update_rate>1000</real_time_update_rate>
    </physics>
    <scene>
      <ambient>0.4 0.4 0.4 1</ambient>
      <background>0.7 0.7 0.7 1</background>
      <shadows>1</shadows>
    </scene>
    <spherical_coordinates>
      <surface_model>EARTH_WGS84</surface_model>
      <latitude_deg>0</latitude_deg>
      <longitude_deg>0</longitude_deg>
      <elevation>0</elevation>
      <heading_deg>0</heading_deg>
    </spherical_coordinates>
    <model name='table'>
      <static>1</static>
      <link name='link'>
        <collision name='surface'>
          <pose frame=''>0 0 1 0 -0 0</pose>
          <geometry>
            <box>
              <size>1.5 0.8 0.03</size>
            </box>
          </geometry>
          <surface>
            <friction>
              <ode>
                <mu>0.6</mu>
                <mu2>0.6</mu2>
              </ode>
              <torsional>
                <ode/>
              </torsional>
            </friction>
            <bounce/>
            <contact>
              <ode/>
            </contact>
          </surface>
          <max_contacts>10</max_contacts>
        </collision>
        <visual name='visual1'>
          <pose frame=''>0 0 1 0 -0 0</pose>
          <geometry>
            <box>
              <size>1.5 0.8 0.03</size>
            </box>
          </geometry>
          <material>
            <script>
              <uri>file://media/materials/scripts/gazebo.material</uri>
              <name>Gazebo/Wood</name>
            </script>
          </material>
        </visual>
        <collision name='front_left_leg'>
          <pose frame=''>0.68 0.38 0.5 0 -0 0</pose>
          <geometry>
            <cylinder>
              <radius>0.02</radius>
              <length>1</length>
            </cylinder>
          </geometry>
          <max_contacts>10</max_contacts>
          <surface>
            <bounce/>
            <friction>
              <ode/>
              <torsional>
                <ode/>
              </torsional>
            </friction>
            <contact>
              <ode/>
            </contact>
          </surface>
        </collision>
        <visual name='front_left_leg'>
          <pose frame=''>0.68 0.38 0.5 0 -0 0</pose>
          <geometry>
            <cylinder>
              <radius>0.02</radius>
              <length>1</length>
            </cylinder>
          </geometry>
          <material>
            <script>
              <uri>file://media/materials/scripts/gazebo.material</uri>
              <name>Gazebo/Grey</name>
            </script>
          </material>
        </visual>
        <collision name='front_right_leg'>
          <pose frame=''>0.68 -0.38 0.5 0 -0 0</pose>
          <geometry>
            <cylinder>
              <radius>0.02</radius>
              <length>1</length>
            </cylinder>
          </geometry>
          <max_contacts>10</max_contacts>
          <surface>
            <bounce/>
            <friction>
              <ode/>
              <torsional>
                <ode/>
              </torsional>
            </friction>
            <contact>
              <ode/>
            </contact>
          </surface>
        </collision>
        <visual name='front_right_leg'>
          <pose frame=''>0.68 -0.38 0.5 0 -0 0</pose>
          <geometry>
            <cylinder>
              <radius>0.02</radius>
              <length>1</length>
            </cylinder>
          </geometry>
          <material>
            <script>
              <uri>file://media/materials/scripts/gazebo.material</uri>
              <name>Gazebo/Grey</name>
            </script>
          </material>
        </visual>
        <collision name='back_right_leg'>
          <pose frame=''>-0.68 -0.38 0.5 0 -0 0</pose>
          <geometry>
            <cylinder>
              <radius>0.02</radius>
              <length>1</length>
            </cylinder>
          </geometry>
          <max_contacts>10</max_contacts>
          <surface>
            <bounce/>
            <friction>
              <ode/>
              <torsional>
                <ode/>
              </torsional>
            </friction>
            <contact>
              <ode/>
            </contact>
          </surface>
        </collision>
        <visual name='back_right_leg'>
          <pose frame=''>-0.68 -0.38 0.5 0 -0 0</pose>
          <geometry>
            <cylinder>
              <radius>0.02</radius>
              <length>1</length>
            </cylinder>
          </geometry>
          <material>
            <script>
              <uri>file://media/materials/scripts/gazebo.material</uri>
              <name>Gazebo/Grey</name>
            </script>
          </material>
        </visual>
        <collision name='back_left_leg'>
          <pose frame=''>-0.68 0.38 0.5 0 -0 0</pose>
          <geometry>
            <cylinder>
              <radius>0.02</radius>
              <length>1</length>
            </cylinder>
          </geometry>
          <max_contacts>10</max_contacts>
          <surface>
            <bounce/>
            <friction>
              <ode/>
              <torsional>
                <ode/>
              </torsional>
            </friction>
            <contact>
              <ode/>
            </contact>
          </surface>
        </collision>
        <visual name='back_left_leg'>
          <pose frame=''>-0.68 0.38 0.5 0 -0 0</pose>
          <geometry>
            <cylinder>
              <radius>0.02</radius>
              <length>1</length>
            </cylinder>
          </geometry>
          <material>
            <script>
              <uri>file://media/materials/scripts/gazebo.material</uri>
              <name>Gazebo/Grey</name>
            </script>
          </material>
        </visual>
        <velocity_decay>
          <linear>0</linear>
          <angular>0</angular>
        </velocity_decay>
        <self_collide>0</self_collide>
        <kinematic>0</kinematic>
        <gravity>1</gravity>
      </link>
      <pose frame=''>1.51029 1 0 0 -0 0</pose>
    </model>
    <state world_name='default'>
      <sim_time>447 290000000</sim_time>
      <real_time>233 151837408</real_time>
      <wall_time>1551381333 148634285</wall_time>
      <iterations>215409</iterations>
      <model name='ground_plane'>
        <pose frame=''>0 0 0 0 -0 0</pose>
        <scale>1 1 1</scale>
        <link name='link'>
          <pose frame=''>0 0 0 0 -0 0</pose>
          <velocity>0 0 0 0 -0 0</velocity>
          <acceleration>0 0 0 0 -0 0</acceleration>
          <wrench>0 0 0 0 -0 0</wrench>
        </link>
      </model>
      <model name='iiwa'>
        <pose frame=''>-0 -0 0 0 -0 0</pose>
        <scale>1 1 1</scale>
        <link name='frame'>
          <pose frame=''>-0 -0 0 0 -0 0</pose>
          <velocity>-0.000108 8e-06 0.000128 5e-06 8.6e-05 -2e-06</velocity>
          <acceleration>0 0 0 0 -0 0</acceleration>
          <wrench>0.072743 -0.332843 0.830072 0 -0 0</wrench>
        </link>
        <link name='iiwa_link_0'>
          <pose frame=''>1.5 0.25 1.9 -3.14159 1e-06 -0</pose>
          <velocity>5.5e-05 -1.2e-05 -0.000175 0.000672 0.000863 7.9e-05</velocity>
          <acceleration>-0.010881 0.053537 -0.176548 -1.79835 1.41574 -2.9829</acceleration>
          <wrench>-0.054405 0.267683 -0.88274 0 -0 0</wrench>
        </link>
        <link name='iiwa_link_1'>
          <pose frame=''>1.5 0.25 1.7425 3.14159 1e-05 -0.49</pose>
          <velocity>-3.7e-05 5.1e-05 -0.000179 0.000445 0.000614 4.9e-05</velocity>
          <acceleration>-0.112161 0.104718 -0.175912 0.48179 0.620579 0.049067</acceleration>
          <wrench>-0.448644 0.418873 -0.703648 0 -0 0</wrench>
        </link>
        <link name='iiwa_link_2'>
          <pose frame=''>1.5 0.250001 1.54 -1.5708 0.30499 2.65159</pose>
          <velocity>-0.000134 0.000114 -0.000168 0.000543 0.000887 4.8e-05</velocity>
          <acceleration>-0.181755 0.14442 -0.188581 0.605659 0.36934 -0.057787</acceleration>
          <wrench>-0.72702 0.577681 -0.754322 0 -0 0</wrench>
        </link>
        <link name='iiwa_link_3'>
          <pose frame=''>1.55418 0.2211 1.34494 -3.08499 -0.299847 -0.679553</pose>
          <velocity>-0.000271 0.000189 -0.000221 0.000172 0.000671 0.000411</velocity>
          <acceleration>-0.338149 0.216958 -0.238852 0.026032 0.752521 0.670029</acceleration>
          <wrench>-1.01445 0.650875 -0.716555 0 -0 0</wrench>
        </link>
        <link name='iiwa_link_4'>
          <pose frame=''>1.61127 0.190645 1.13938 -1.5159 0.173444 -0.65333</pose>
          <velocity>-0.000368 0.000225 -0.000269 0.000266 0.000742 0.000275</velocity>
          <acceleration>-0.42584 0.245547 -0.269885 0.326683 0.182484 0.764161</acceleration>
          <wrench>-1.14977 0.662977 -0.72869 0 -0 0</wrench>
        </link>
        <link name='iiwa_link_5'>
          <pose frame=''>1.59218 0.218008 0.957923 -3.1415 -0.181842 2.17948</pose>
          <velocity>-0.00048 0.000245 -0.000255 0.000156 0.000604 0.000186</velocity>
          <acceleration>-0.529673 0.25812 -0.256702 0.189783 0.579757 -0.008862</acceleration>
          <wrench>-0.900443 0.438803 -0.436394 0 -0 0</wrench>
        </link>
        <link name='iiwa_link_6'>
          <pose frame=''>1.56988 0.249969 0.745976 -1.57071 0.000158 2.17949</pose>
          <velocity>-0.000593 0.000259 -0.000244 0.000208 0.000563 0.000238</velocity>
          <acceleration>-0.593125 0.258587 -0.243687 0.228872 0.420099 0.311169</acceleration>
          <wrench>-1.06763 0.465457 -0.438637 0 -0 0</wrench>
        </link>
        <link name='iiwa_link_7'>
          <pose frame=''>1.56988 0.249954 0.664976 3.1415 -0.000157 -0.962095</pose>
          <velocity>-0.000628 0.000269 -0.000246 0.00018 0.000514 0.000246</velocity>
          <acceleration>-0.638529 0.272939 -0.24574 0.180355 0.514061 0.24627</acceleration>
          <wrench>-0.191559 0.081882 -0.073722 0 -0 0</wrench>
        </link>
      </model>
      <model name='table'>
        <pose frame=''>1.51029 0.25 -0.51378 0 -0 0</pose>
        <scale>1 1 1</scale>
        <link name='link'>
          <pose frame=''>1.51029 0.25 -0.51378 0 -0 0</pose>
          <velocity>0 0 0 0 -0 0</velocity>
          <acceleration>0 0 0 0 -0 0</acceleration>
          <wrench>0 0 0 0 -0 0</wrench>
        </link>
      </model>
      <model name='unit_box'>
        <pose frame=''>1.35697 0.191269 0.567477 -5e-06 5e-06 0.222487</pose>
        <scale>0.234111 0.248237 0.132517</scale>
        <link name='link'>
          <pose frame=''>1.35697 0.191269 0.567477 -5e-06 5e-06 0.222487</pose>
          <velocity>0 0 0 0 -0 0</velocity>
          <acceleration>0.217317 0.367828 -3.33512 -2.40983 -0.138248 -3.14159</acceleration>
          <wrench>0.217317 0.367828 -3.33512 0 -0 0</wrench>
        </link>
      </model>
      <light name='sun'>
        <pose frame=''>0 0 10 0 -0 0</pose>
      </light>
    </state>
    <gui fullscreen='0'>
      <camera name='user_camera'>
        <pose frame=''>1.44997 -1.77485 1.8228 0 0.58314 1.26636</pose>
        <view_controller>orbit</view_controller>
        <projection_type>perspective</projection_type>
      </camera>
    </gui>
    <model name='unit_box'>
      <pose frame=''>1.7398 -1.39831 0.5 0 -0 0</pose>
      <link name='link'>
        <inertial>
          <mass>1</mass>
          <inertia>
            <ixx>0.166667</ixx>
            <ixy>0</ixy>
            <ixz>0</ixz>
            <iyy>0.166667</iyy>
            <iyz>0</iyz>
            <izz>0.166667</izz>
          </inertia>
        </inertial>
        <collision name='collision'>
          <geometry>
            <box>
              <size>1 0.999996 0.999992</size>
            </box>
          </geometry>
          <max_contacts>10</max_contacts>
          <surface>
            <contact>
              <ode/>
            </contact>
            <bounce/>
            <friction>
              <torsional>
                <ode/>
              </torsional>
              <ode/>
            </friction>
          </surface>
        </collision>
        <visual name='visual'>
          <geometry>
            <box>
              <size>1 0.999996 0.999992</size>
            </box>
          </geometry>
          <material>
            <script>
              <name>Gazebo/Grey</name>
              <uri>file://media/materials/scripts/gazebo.material</uri>
            </script>
          </material>
        </visual>
        <self_collide>0</self_collide>
        <kinematic>0</kinematic>
      </link>
    </model>
    <model name='iiwa'>
      <link name='frame'>
        <pose frame=''>0 0 0 0 -0 0</pose>
        <inertial>
          <pose frame=''>1.5 0.25 1.25 0 -0 0</pose>
          <mass>2697</mass>
          <inertia>
            <ixx>0</ixx>
            <ixy>0</ixy>
            <ixz>0</ixz>
            <iyy>0</iyy>
            <iyz>0</iyz>
            <izz>0</izz>
          </inertia>
        </inertial>
        <collision name='frame_collision'>
          <pose frame=''>0 0 0 0 -0 0</pose>
          <geometry>
            <mesh>
              <scale>1 1 1</scale>
              <uri>/home/juan/catkin_kuka/src/kuka-iiwa/iiwa_description/meshes/iiwa14/collision/base_link.STL</uri>
            </mesh>
          </geometry>
          <surface>
            <contact>
              <ode/>
            </contact>
            <friction>
              <ode>
                <mu>0.2</mu>
                <mu2>0.2</mu2>
              </ode>
              <torsional>
                <ode/>
              </torsional>
            </friction>
            <bounce/>
          </surface>
          <max_contacts>10</max_contacts>
        </collision>
        <visual name='frame_visual'>
          <pose frame=''>0 0 0 0 -0 0</pose>
          <geometry>
            <mesh>
              <scale>1 1 1</scale>
              <uri>/home/juan/catkin_kuka/src/kuka-iiwa/iiwa_description/meshes/iiwa14/visual/base_link.STL</uri>
            </mesh>
          </geometry>
          <material>
            <script>
              <name>Gazebo/White</name>
              <uri>file://media/materials/scripts/gazebo.material</uri>
            </script>
          </material>
        </visual>
        <gravity>1</gravity>
        <velocity_decay/>
        <self_collide>1</self_collide>
        <kinematic>0</kinematic>
      </link>
      <joint name='fixed' type='fixed'>
        <child>frame</child>
        <parent>world</parent>
      </joint>
      <link name='iiwa_link_0'>
        <pose frame=''>1.5 0.25 1.9 3.14159 -0 0</pose>
        <inertial>
          <pose frame=''>-0.1 0 0.07 0 -0 0</pose>
          <mass>5</mass>
          <inertia>
            <ixx>0.05</ixx>
            <ixy>0</ixy>
            <ixz>0</ixz>
            <iyy>0.06</iyy>
            <iyz>0</iyz>
            <izz>0.03</izz>
          </inertia>
        </inertial>
        <collision name='iiwa_link_0_collision'>
          <pose frame=''>0 0 0 0 -0 0</pose>
          <geometry>
            <mesh>
              <scale>1 1 1</scale>
              <uri>/home/juan/catkin_kuka/src/kuka-iiwa/iiwa_description/meshes/iiwa14/collision/link_0.stl</uri>
            </mesh>
          </geometry>
          <surface>
            <contact>
              <ode/>
            </contact>
            <friction>
              <ode>
                <mu>0.2</mu>
                <mu2>0.2</mu2>
              </ode>
              <torsional>
                <ode/>
              </torsional>
            </friction>
            <bounce/>
          </surface>
          <max_contacts>10</max_contacts>
        </collision>
        <visual name='iiwa_link_0_visual'>
          <pose frame=''>0 0 0 0 -0 0</pose>
          <geometry>
            <mesh>
              <scale>1 1 1</scale>
              <uri>/home/juan/catkin_kuka/src/kuka-iiwa/iiwa_description/meshes/iiwa14/visual/link_0.stl</uri>
            </mesh>
          </geometry>
          <material>
            <script>
              <name>Gazebo/Grey</name>
              <uri>file://media/materials/scripts/gazebo.material</uri>
            </script>
          </material>
        </visual>
        <gravity>1</gravity>
        <velocity_decay/>
        <self_collide>1</self_collide>
        <kinematic>0</kinematic>
      </link>
      <joint name='world_iiwa_joint' type='fixed'>
        <child>iiwa_link_0</child>
        <parent>world</parent>
      </joint>
      <link name='iiwa_link_1'>
        <pose frame=''>1.5 0.25 1.7425 3.14159 -0 0</pose>
        <inertial>
          <pose frame=''>0 -0.03 0.12 0 -0 0</pose>
          <mass>4</mass>
          <inertia>
            <ixx>0.1</ixx>
            <ixy>0</ixy>
            <ixz>0</ixz>
            <iyy>0.09</iyy>
            <iyz>0</iyz>
            <izz>0.02</izz>
          </inertia>
        </inertial>
        <collision name='iiwa_link_1_collision'>
          <pose frame=''>0 0 0 0 -0 0</pose>
          <geometry>
            <mesh>
              <scale>1 1 1</scale>
              <uri>/home/juan/catkin_kuka/src/kuka-iiwa/iiwa_description/meshes/iiwa14/collision/link_1.stl</uri>
            </mesh>
          </geometry>
          <surface>
            <contact>
              <ode/>
            </contact>
            <friction>
              <ode>
                <mu>0.2</mu>
                <mu2>0.2</mu2>
              </ode>
              <torsional>
                <ode/>
              </torsional>
            </friction>
            <bounce/>
          </surface>
          <max_contacts>10</max_contacts>
        </collision>
        <visual name='iiwa_link_1_visual'>
          <pose frame=''>0 0 0 0 -0 0</pose>
          <geometry>
            <mesh>
              <scale>1 1 1</scale>
              <uri>/home/juan/catkin_kuka/src/kuka-iiwa/iiwa_description/meshes/iiwa14/visual/link_1.stl</uri>
            </mesh>
          </geometry>
          <material>
            <script>
              <name>Gazebo/White</name>
              <uri>file://media/materials/scripts/gazebo.material</uri>
            </script>
          </material>
        </visual>
        <gravity>1</gravity>
        <velocity_decay/>
        <self_collide>1</self_collide>
        <kinematic>0</kinematic>
      </link>
      <joint name='iiwa_joint_1' type='revolute'>
        <child>iiwa_link_1</child>
        <parent>iiwa_link_0</parent>
        <axis>
          <xyz>0 0 -1</xyz>
          <limit>
            <lower>-2.96706</lower>
            <upper>2.96706</upper>
            <effort>300</effort>
            <velocity>10</velocity>
          </limit>
          <dynamics>
            <damping>0.5</damping>
            <friction>0</friction>
            <spring_reference>0</spring_reference>
            <spring_stiffness>0</spring_stiffness>
          </dynamics>
          <use_parent_model_frame>1</use_parent_model_frame>
        </axis>
      </joint>
      <link name='iiwa_link_2'>
        <pose frame=''>1.5 0.25 1.54 -1.5708 -0 3.14159</pose>
        <inertial>
          <pose frame=''>0.0003 0.059 0.042 0 -0 0</pose>
          <mass>4</mass>
          <inertia>
            <ixx>0.05</ixx>
            <ixy>0</ixy>
            <ixz>0</ixz>
            <iyy>0.018</iyy>
            <iyz>0</iyz>
            <izz>0.044</izz>
          </inertia>
        </inertial>
        <collision name='iiwa_link_2_collision'>
          <pose frame=''>0 0 0 0 -0 0</pose>
          <geometry>
            <mesh>
              <scale>1 1 1</scale>
              <uri>/home/juan/catkin_kuka/src/kuka-iiwa/iiwa_description/meshes/iiwa14/collision/link_2.stl</uri>
            </mesh>
          </geometry>
          <surface>
            <contact>
              <ode/>
            </contact>
            <friction>
              <ode>
                <mu>0.2</mu>
                <mu2>0.2</mu2>
              </ode>
              <torsional>
                <ode/>
              </torsional>
            </friction>
            <bounce/>
          </surface>
          <max_contacts>10</max_contacts>
        </collision>
        <visual name='iiwa_link_2_visual'>
          <pose frame=''>0 0 0 0 -0 0</pose>
          <geometry>
            <mesh>
              <scale>1 1 1</scale>
              <uri>/home/juan/catkin_kuka/src/kuka-iiwa/iiwa_description/meshes/iiwa14/visual/link_2.stl</uri>
            </mesh>
          </geometry>
          <material>
            <script>
              <name>Gazebo/White</name>
              <uri>file://media/materials/scripts/gazebo.material</uri>
            </script>
          </material>
        </visual>
        <gravity>1</gravity>
        <velocity_decay/>
        <self_collide>1</self_collide>
        <kinematic>0</kinematic>
      </link>
      <joint name='iiwa_joint_2' type='revolute'>
        <child>iiwa_link_2</child>
        <parent>iiwa_link_1</parent>
        <axis>
          <xyz>0 -1 0</xyz>
          <limit>
            <lower>-2.0944</lower>
            <upper>2.0944</upper>
            <effort>300</effort>
            <velocity>10</velocity>
          </limit>
          <dynamics>
            <damping>0.5</damping>
            <friction>0</friction>
            <spring_reference>0</spring_reference>
            <spring_stiffness>0</spring_stiffness>
          </dynamics>
          <use_parent_model_frame>1</use_parent_model_frame>
        </axis>
      </joint>
      <link name='iiwa_link_3'>
        <pose frame=''>1.5 0.25 1.3355 3.14159 -0 0</pose>
        <inertial>
          <pose frame=''>0 0.03 0.13 0 -0 0</pose>
          <mass>3</mass>
          <inertia>
            <ixx>0.08</ixx>
            <ixy>0</ixy>
            <ixz>0</ixz>
            <iyy>0.075</iyy>
            <iyz>0</iyz>
            <izz>0.01</izz>
          </inertia>
        </inertial>
        <collision name='iiwa_link_3_collision'>
          <pose frame=''>0 0 0 0 -0 0</pose>
          <geometry>
            <mesh>
              <scale>1 1 1</scale>
              <uri>/home/juan/catkin_kuka/src/kuka-iiwa/iiwa_description/meshes/iiwa14/collision/link_3.stl</uri>
            </mesh>
          </geometry>
          <surface>
            <contact>
              <ode/>
            </contact>
            <friction>
              <ode>
                <mu>0.2</mu>
                <mu2>0.2</mu2>
              </ode>
              <torsional>
                <ode/>
              </torsional>
            </friction>
            <bounce/>
          </surface>
          <max_contacts>10</max_contacts>
        </collision>
        <visual name='iiwa_link_3_visual'>
          <pose frame=''>0 0 0 0 -0 0</pose>
          <geometry>
            <mesh>
              <scale>1 1 1</scale>
              <uri>/home/juan/catkin_kuka/src/kuka-iiwa/iiwa_description/meshes/iiwa14/visual/link_3.stl</uri>
            </mesh>
          </geometry>
          <material>
            <script>
              <name>Gazebo/White</name>
              <uri>file://media/materials/scripts/gazebo.material</uri>
            </script>
          </material>
        </visual>
        <gravity>1</gravity>
        <velocity_decay/>
        <self_collide>1</self_collide>
        <kinematic>0</kinematic>
      </link>
      <joint name='iiwa_joint_3' type='revolute'>
        <child>iiwa_link_3</child>
        <parent>iiwa_link_2</parent>
        <axis>
          <xyz>0 0 -1</xyz>
          <limit>
            <lower>-2.96706</lower>
            <upper>2.96706</upper>
            <effort>300</effort>
            <velocity>10</velocity>
          </limit>
          <dynamics>
            <damping>0.5</damping>
            <friction>0</friction>
            <spring_reference>0</spring_reference>
            <spring_stiffness>0</spring_stiffness>
          </dynamics>
          <use_parent_model_frame>1</use_parent_model_frame>
        </axis>
      </joint>
      <link name='iiwa_link_4'>
        <pose frame=''>1.5 0.25 1.12 -1.5708 -0 -0</pose>
        <inertial>
          <pose frame=''>0 0.067 0.034 0 -0 0</pose>
          <mass>2.7</mass>
          <inertia>
            <ixx>0.03</ixx>
            <ixy>0</ixy>
            <ixz>0</ixz>
            <iyy>0.01</iyy>
            <iyz>0</iyz>
            <izz>0.029</izz>
          </inertia>
        </inertial>
        <collision name='iiwa_link_4_collision'>
          <pose frame=''>0 0 0 0 -0 0</pose>
          <geometry>
            <mesh>
              <scale>1 1 1</scale>
              <uri>/home/juan/catkin_kuka/src/kuka-iiwa/iiwa_description/meshes/iiwa14/collision/link_4.stl</uri>
            </mesh>
          </geometry>
          <surface>
            <contact>
              <ode/>
            </contact>
            <friction>
              <ode>
                <mu>0.2</mu>
                <mu2>0.2</mu2>
              </ode>
              <torsional>
                <ode/>
              </torsional>
            </friction>
            <bounce/>
          </surface>
          <max_contacts>10</max_contacts>
        </collision>
        <visual name='iiwa_link_4_visual'>
          <pose frame=''>0 0 0 0 -0 0</pose>
          <geometry>
            <mesh>
              <scale>1 1 1</scale>
              <uri>/home/juan/catkin_kuka/src/kuka-iiwa/iiwa_description/meshes/iiwa14/visual/link_4.stl</uri>
            </mesh>
          </geometry>
          <material>
            <script>
              <name>Gazebo/White</name>
              <uri>file://media/materials/scripts/gazebo.material</uri>
            </script>
          </material>
        </visual>
        <gravity>1</gravity>
        <velocity_decay/>
        <self_collide>1</self_collide>
        <kinematic>0</kinematic>
      </link>
      <joint name='iiwa_joint_4' type='revolute'>
        <child>iiwa_link_4</child>
        <parent>iiwa_link_3</parent>
        <axis>
          <xyz>0 1 0</xyz>
          <limit>
            <lower>-2.0944</lower>
            <upper>2.0944</upper>
            <effort>300</effort>
            <velocity>10</velocity>
          </limit>
          <dynamics>
            <damping>0.5</damping>
            <friction>0</friction>
            <spring_reference>0</spring_reference>
            <spring_stiffness>0</spring_stiffness>
          </dynamics>
          <use_parent_model_frame>1</use_parent_model_frame>
        </axis>
      </joint>
      <link name='iiwa_link_5'>
        <pose frame=''>1.5 0.25 0.9355 -3.14159 -0 3.14159</pose>
        <inertial>
          <pose frame=''>0.0001 0.021 0.076 0 -0 0</pose>
          <mass>1.7</mass>
          <inertia>
            <ixx>0.02</ixx>
            <ixy>0</ixy>
            <ixz>0</ixz>
            <iyy>0.018</iyy>
            <iyz>0</iyz>
            <izz>0.005</izz>
          </inertia>
        </inertial>
        <collision name='iiwa_link_5_collision'>
          <pose frame=''>0 0 0 0 -0 0</pose>
          <geometry>
            <mesh>
              <scale>1 1 1</scale>
              <uri>/home/juan/catkin_kuka/src/kuka-iiwa/iiwa_description/meshes/iiwa14/collision/link_5.stl</uri>
            </mesh>
          </geometry>
          <surface>
            <contact>
              <ode/>
            </contact>
            <friction>
              <ode>
                <mu>0.2</mu>
                <mu2>0.2</mu2>
              </ode>
              <torsional>
                <ode/>
              </torsional>
            </friction>
            <bounce/>
          </surface>
          <max_contacts>10</max_contacts>
        </collision>
        <visual name='iiwa_link_5_visual'>
          <pose frame=''>0 0 0 0 -0 0</pose>
          <geometry>
            <mesh>
              <scale>1 1 1</scale>
              <uri>/home/juan/catkin_kuka/src/kuka-iiwa/iiwa_description/meshes/iiwa14/visual/link_5.stl</uri>
            </mesh>
          </geometry>
          <material>
            <script>
              <name>Gazebo/White</name>
              <uri>file://media/materials/scripts/gazebo.material</uri>
            </script>
          </material>
        </visual>
        <gravity>1</gravity>
        <velocity_decay/>
        <self_collide>1</self_collide>
        <kinematic>0</kinematic>
      </link>
      <joint name='iiwa_joint_5' type='revolute'>
        <child>iiwa_link_5</child>
        <parent>iiwa_link_4</parent>
        <axis>
          <xyz>0 0 -1</xyz>
          <limit>
            <lower>-2.96706</lower>
            <upper>2.96706</upper>
            <effort>300</effort>
            <velocity>10</velocity>
          </limit>
          <dynamics>
            <damping>0.5</damping>
            <friction>0</friction>
            <spring_reference>0</spring_reference>
            <spring_stiffness>0</spring_stiffness>
          </dynamics>
          <use_parent_model_frame>1</use_parent_model_frame>
        </axis>
      </joint>
      <link name='iiwa_link_6'>
        <pose frame=''>1.5 0.25 0.72 -1.5708 -0 3.14159</pose>
        <inertial>
          <pose frame=''>0 0.0006 0.0004 0 -0 0</pose>
          <mass>1.8</mass>
          <inertia>
            <ixx>0.005</ixx>
            <ixy>0</ixy>
            <ixz>0</ixz>
            <iyy>0.0036</iyy>
            <iyz>0</iyz>
            <izz>0.0047</izz>
          </inertia>
        </inertial>
        <collision name='iiwa_link_6_collision'>
          <pose frame=''>0 0 0 0 -0 0</pose>
          <geometry>
            <mesh>
              <scale>1 1 1</scale>
              <uri>/home/juan/catkin_kuka/src/kuka-iiwa/iiwa_description/meshes/iiwa14/collision/link_6.stl</uri>
            </mesh>
          </geometry>
          <surface>
            <contact>
              <ode/>
            </contact>
            <friction>
              <ode>
                <mu>0.2</mu>
                <mu2>0.2</mu2>
              </ode>
              <torsional>
                <ode/>
              </torsional>
            </friction>
            <bounce/>
          </surface>
          <max_contacts>10</max_contacts>
        </collision>
        <visual name='iiwa_link_6_visual'>
          <pose frame=''>0 0 0 0 -0 0</pose>
          <geometry>
            <mesh>
              <scale>1 1 1</scale>
              <uri>/home/juan/catkin_kuka/src/kuka-iiwa/iiwa_description/meshes/iiwa14/visual/link_6.stl</uri>
            </mesh>
          </geometry>
          <material>
            <script>
              <name>Gazebo/White</name>
              <uri>file://media/materials/scripts/gazebo.material</uri>
            </script>
          </material>
        </visual>
        <gravity>1</gravity>
        <velocity_decay/>
        <self_collide>1</self_collide>
        <kinematic>0</kinematic>
      </link>
      <joint name='iiwa_joint_6' type='revolute'>
        <child>iiwa_link_6</child>
        <parent>iiwa_link_5</parent>
        <axis>
          <xyz>0 -1 0</xyz>
          <limit>
            <lower>-2.0944</lower>
            <upper>2.0944</upper>
            <effort>300</effort>
            <velocity>10</velocity>
          </limit>
          <dynamics>
            <damping>0.5</damping>
            <friction>0</friction>
            <spring_reference>0</spring_reference>
            <spring_stiffness>0</spring_stiffness>
          </dynamics>
          <use_parent_model_frame>1</use_parent_model_frame>
        </axis>
      </joint>
      <link name='iiwa_link_7'>
        <pose frame=''>1.5 0.25 0.639 3.14159 -0 0</pose>
        <inertial>
          <pose frame=''>0 0 0.02 0 -0 0</pose>
          <mass>0.3</mass>
          <inertia>
            <ixx>0.001</ixx>
            <ixy>0</ixy>
            <ixz>0</ixz>
            <iyy>0.001</iyy>
            <iyz>0</iyz>
            <izz>0.001</izz>
          </inertia>
        </inertial>
        <collision name='iiwa_link_7_collision'>
          <pose frame=''>0 0 0 0 -0 0</pose>
          <geometry>
            <mesh>
              <scale>1 1 1</scale>
              <uri>/home/juan/catkin_kuka/src/kuka-iiwa/iiwa_description/meshes/iiwa14/collision/link_7.stl</uri>
            </mesh>
          </geometry>
          <surface>
            <contact>
              <ode/>
            </contact>
            <friction>
              <ode>
                <mu>0.2</mu>
                <mu2>0.2</mu2>
              </ode>
              <torsional>
                <ode/>
              </torsional>
            </friction>
            <bounce/>
          </surface>
          <max_contacts>10</max_contacts>
        </collision>
        <visual name='iiwa_link_7_visual'>
          <pose frame=''>0 0 0 0 -0 0</pose>
          <geometry>
            <mesh>
              <scale>1 1 1</scale>
              <uri>/home/juan/catkin_kuka/src/kuka-iiwa/iiwa_description/meshes/iiwa14/visual/link_7.stl</uri>
            </mesh>
          </geometry>
          <material>
            <script>
              <name>Gazebo/Grey</name>
              <uri>file://media/materials/scripts/gazebo.material</uri>
            </script>
          </material>
        </visual>
        <velocity_decay/>
        <self_collide>1</self_collide>
        <gravity>1</gravity>
        <velocity_decay/>
        <kinematic>0</kinematic>
      </link>
      <joint name='iiwa_joint_7' type='revolute'>
        <child>iiwa_link_7</child>
        <parent>iiwa_link_6</parent>
        <axis>
          <xyz>0 0 -1</xyz>
          <limit>
            <lower>-3.05433</lower>
            <upper>3.05433</upper>
            <effort>300</effort>
            <velocity>10</velocity>
          </limit>
          <dynamics>
            <damping>0.5</damping>
            <friction>0</friction>
            <spring_reference>0</spring_reference>
            <spring_stiffness>0</spring_stiffness>
          </dynamics>
          <use_parent_model_frame>1</use_parent_model_frame>
        </axis>
        <physics>
          <provide_feedback>1</provide_feedback>
          <ode>
            <provide_feedback>1</provide_feedback>
            <limit>
              <cfm>0</cfm>
              <erp>0.2</erp>
            </limit>
          </ode>
        </physics>
      </joint>
      <plugin name='gazebo_ros_control' filename='libgazebo_ros_control.so'>
        <robotNamespace>/iiwa</robotNamespace>
      </plugin>
      <static>0</static>
      <plugin name='gazebo_ros_ft_sensor' filename='libgazebo_ros_ft_sensor.so'>
        <robotNamespace>/iiwa</robotNamespace>
        <topicName>ft_sensor_data</topicName>
        <jointName>iiwa_joint_7</jointName>
        <updateRate>10</updateRate>
      </plugin>
      <pose frame=''>0 0 0 0 -0 0</pose>
    </model>
  </world>
</sdf>
