<robot
  name="dual_arm_wo_wrist">
  <link
    name="base_link">
    <inertial>
      <origin
        xyz="-0.0746188127206767 5.55111512312578E-17 0.0854799809858156"
        rpy="0 0 0" />
      <mass
        value="81.613834759363" />
      <inertia
        ixx="0"
        ixy="0"
        ixz="0"
        iyy="0"
        iyz="0"
        izz="0" />
    </inertial>
    <visual>
      <origin
        xyz="0 0 0"
        rpy="0 0 0" />
      <geometry>
        <mesh
          filename="package://dual_arm_wo_wrist/meshes/base_link.STL" />
      </geometry>
      <material
        name="">
        <color
          rgba="1 1 1 1" />
      </material>
    </visual>
    <collision>
      <origin
        xyz="0 0 0"
        rpy="0 0 0" />
      <geometry>
        <mesh
          filename="package://dual_arm_wo_wrist/meshes/base_link.STL" />
      </geometry>
    </collision>
  </link>
  <link
    name="L1_1">
    <inertial>
      <origin
        xyz="0.00330190025294513 0.0010848045406151 -0.0196609281088113"
        rpy="0 0 0" />
      <mass
        value="0.323347358064715" />
      <inertia
        ixx="9.68253685624809E-05"
        ixy="-1.59383421010915E-06"
        ixz="1.69151536635019E-05"
        iyy="0.000101153002835933"
        iyz="5.55729552349029E-06"
        izz="5.37490914918669E-06" />
    </inertial>
    <visual>
      <origin
        xyz="0 0 0"
        rpy="0 0 0" />
      <geometry>
        <mesh
          filename="package://dual_arm_wo_wrist/meshes/L1_1.STL" />
      </geometry>
      <material
        name="">
        <color
          rgba="1 1 1 1" />
      </material>
    </visual>
    <collision>
      <origin
        xyz="0 0 0"
        rpy="0 0 0" />
      <geometry>
        <mesh
          filename="package://dual_arm_wo_wrist/meshes/L1_1.STL" />
      </geometry>
    </collision>
  </link>
  <joint
    name="J_11"
    type="revolute">
    <origin
      xyz="-0.0744445637977387 -0.152871273073738 0.110435575211296"
      rpy="1.70908117298887 0.775712981728982 -2.94539473140516" />
    <parent
      link="base_link" />
    <child
      link="L1_1" />
    <axis
      xyz="0 0 -1" />
  </joint>
  <link
    name="L1_2">
    <inertial>
      <origin
        xyz="-0.0595754729218855 -7.04107574474311E-05 0.000476396292132808"
        rpy="0 0 0" />
      <mass
        value="0.227601605228897" />
      <inertia
        ixx="1.67315392108185E-06"
        ixy="-7.705302782939E-07"
        ixz="9.78556384683632E-06"
        iyy="0.000751270236328134"
        iyz="1.46402067480785E-08"
        izz="0.000750888308838527" />
    </inertial>
    <visual>
      <origin
        xyz="0 0 0"
        rpy="0 0 0" />
      <geometry>
        <mesh
          filename="package://dual_arm_wo_wrist/meshes/L1_2.STL" />
      </geometry>
      <material
        name="">
        <color
          rgba="0.898039215686275 0.898039215686275 0.898039215686275 1" />
      </material>
    </visual>
    <collision>
      <origin
        xyz="0 0 0"
        rpy="0 0 0" />
      <geometry>
        <mesh
          filename="package://dual_arm_wo_wrist/meshes/L1_2.STL" />
      </geometry>
    </collision>
  </link>
  <joint
    name="J_12"
    type="revolute">
    <origin
      xyz="0 0 -0.0635"
      rpy="1.5707963267949 -0.380374098489847 0.317429885556193" />
    <parent
      link="L1_1" />
    <child
      link="L1_2" />
    <axis
      xyz="-0.371267855487522 -0.928525809809128 0" />
  </joint>
  <link
    name="L1_3">
    <inertial>
      <origin
        xyz="0.00293314151063553 1.81490356632175E-08 0.0290133398400998"
        rpy="0 0 0" />
      <mass
        value="0.11831755919013" />
      <inertia
        ixx="9.92481356634434E-05"
        ixy="-1.51552648502854E-11"
        ixz="-3.13085577093194E-06"
        iyy="0.000106164353672326"
        iyz="-3.89010332648659E-11"
        izz="6.91621800897355E-06" />
    </inertial>
    <visual>
      <origin
        xyz="0 0 0"
        rpy="0 0 0" />
      <geometry>
        <mesh
          filename="package://dual_arm_wo_wrist/meshes/L1_3.STL" />
      </geometry>
      <material
        name="">
        <color
          rgba="0.898039215686275 0.917647058823529 0.929411764705882 1" />
      </material>
    </visual>
    <collision>
      <origin
        xyz="0 0 0"
        rpy="0 0 0" />
      <geometry>
        <mesh
          filename="package://dual_arm_wo_wrist/meshes/L1_3.STL" />
      </geometry>
    </collision>
  </link>
  <joint
    name="J_13"
    type="revolute">
    <origin
      xyz="-0.178688999999997 -0.000126999999998864 0"
      rpy="-1.57079632679487 1.33226762955019E-15 1.5707963267949" />
    <parent
      link="L1_2" />
    <child
      link="L1_3" />
    <axis
      xyz="-0.928525809809128 0 0.371267855487521" />
  </joint>
  <link
    name="L1_4">
    <inertial>
      <origin
        xyz="1.07414077632484E-14 -0.061997236186389 -0.000687116523836878"
        rpy="0 0 0" />
      <mass
        value="0.0525484699752677" />
      <inertia
        ixx="7.42549840447539E-05"
        ixy="1.26982679589832E-17"
        ixz="-3.84552958053452E-19"
        iyy="2.04469292095451E-07"
        iyz="2.23852937258278E-06"
        izz="7.40505147526585E-05" />
    </inertial>
    <visual>
      <origin
        xyz="0 0 0"
        rpy="0 0 0" />
      <geometry>
        <mesh
          filename="package://dual_arm_wo_wrist/meshes/L1_4.STL" />
      </geometry>
      <material
        name="">
        <color
          rgba="1 1 1 1" />
      </material>
    </visual>
    <collision>
      <origin
        xyz="0 0 0"
        rpy="0 0 0" />
      <geometry>
        <mesh
          filename="package://dual_arm_wo_wrist/meshes/L1_4.STL" />
      </geometry>
    </collision>
  </link>
  <joint
    name="J_14"
    type="revolute">
    <origin
      xyz="0.0266699999999994 0 0.0609600000000023"
      rpy="-1.5707963267949 0.697503960589116 -1.5707963267949" />
    <parent
      link="L1_3" />
    <child
      link="L1_4" />
    <axis
      xyz="-0.238467796238905 -0.284557429485268 -0.928525809809128" />
  </joint>
  <link
    name="L2_1">
    <inertial>
      <origin
        xyz="0.00148034159698374 0.000384598576449902 -0.0196609281024731"
        rpy="0 0 0" />
      <mass
        value="0.323347358064715" />
      <inertia
        ixx="0.000100009530730105"
        ixy="2.48622361406855E-06"
        ixz="9.91585577546079E-06"
        iyy="9.79688404639174E-05"
        iyz="-1.47878923001656E-05"
        izz="5.37490913403388E-06" />
    </inertial>
    <visual>
      <origin
        xyz="0 0 0"
        rpy="0 0 0" />
      <geometry>
        <mesh
          filename="package://dual_arm_wo_wrist/meshes/L2_1.STL" />
      </geometry>
      <material
        name="">
        <color
          rgba="1 1 1 1" />
      </material>
    </visual>
    <collision>
      <origin
        xyz="0 0 0"
        rpy="0 0 0" />
      <geometry>
        <mesh
          filename="package://dual_arm_wo_wrist/meshes/L2_1.STL" />
      </geometry>
    </collision>
  </link>
  <joint
    name="J_21"
    type="revolute">
    <origin
      xyz="-0.0770764780846112 0.152934634404308 0.112429906455408"
      rpy="-1.70908117298887 0.775712981728982 2.94539473140516" />
    <parent
      link="base_link" />
    <child
      link="L2_1" />
    <axis
      xyz="0 0 1" />
  </joint>
  <link
    name="L2_2">
    <inertial>
      <origin
        xyz="-0.0595754434495103 7.03955788072808E-05 -0.000476404287072546"
        rpy="0 0 0" />
      <mass
        value="0.22760154392691" />
      <inertia
        ixx="1.67315853969856E-06"
        ixy="7.7041962317435E-07"
        ixz="-9.78561827297034E-06"
        iyy="0.000751269843750538"
        iyz="1.46357465462174E-08"
        izz="0.000750887910882762" />
    </inertial>
    <visual>
      <origin
        xyz="0 0 0"
        rpy="0 0 0" />
      <geometry>
        <mesh
          filename="package://dual_arm_wo_wrist/meshes/L2_2.STL" />
      </geometry>
      <material
        name="">
        <color
          rgba="0.898039215686275 0.898039215686275 0.898039215686275 1" />
      </material>
    </visual>
    <collision>
      <origin
        xyz="0 0 0"
        rpy="0 0 0" />
      <geometry>
        <mesh
          filename="package://dual_arm_wo_wrist/meshes/L2_2.STL" />
      </geometry>
    </collision>
  </link>
  <joint
    name="J_22"
    type="revolute">
    <origin
      xyz="-0.000455269948952688 0.00327124958639424 -0.0634999999999996"
      rpy="-1.5707963267949 -0.380374098489845 -0.980117794662899" />
    <parent
      link="L2_1" />
    <child
      link="L2_2" />
    <axis
      xyz="0.371267855487522 -0.928525809809128 0" />
  </joint>
  <link
    name="L2_3">
    <inertial>
      <origin
        xyz="0.00293314663648594 2.02260276305211E-08 0.0290133474503437"
        rpy="0 0 0" />
      <mass
        value="0.118317581697963" />
      <inertia
        ixx="9.92481609006769E-05"
        ixy="-1.68896581782303E-11"
        ixz="-3.13087023494145E-06"
        iyy="0.000106164386349057"
        iyz="-4.33529137147844E-11"
        izz="6.91622544849394E-06" />
    </inertial>
    <visual>
      <origin
        xyz="0 0 0"
        rpy="0 0 0" />
      <geometry>
        <mesh
          filename="package://dual_arm_wo_wrist/meshes/L2_3.STL" />
      </geometry>
      <material
        name="">
        <color
          rgba="1 1 1 1" />
      </material>
    </visual>
    <collision>
      <origin
        xyz="0 0 0"
        rpy="0 0 0" />
      <geometry>
        <mesh
          filename="package://dual_arm_wo_wrist/meshes/L2_3.STL" />
      </geometry>
    </collision>
  </link>
  <joint
    name="J_23"
    type="revolute">
    <origin
      xyz="-0.178688999999998 0.000126999999999489 0"
      rpy="1.57079632679492 -1.38777878078145E-15 -1.5707963267949" />
    <parent
      link="L2_2" />
    <child
      link="L2_3" />
    <axis
      xyz="0.928525809809128 0 -0.371267855487521" />
  </joint>
  <link
    name="L2_4">
    <inertial>
      <origin
        xyz="1.08801856413265E-14 -0.0619972361863879 -0.000687116523836656"
        rpy="0 0 0" />
      <mass
        value="0.052548469975267" />
      <inertia
        ixx="7.42549840447516E-05"
        ixy="1.26643601713135E-17"
        ixz="-3.86247023947961E-19"
        iyy="2.04469292095454E-07"
        iyz="2.23852937258277E-06"
        izz="7.40505147526561E-05" />
    </inertial>
    <visual>
      <origin
        xyz="0 0 0"
        rpy="0 0 0" />
      <geometry>
        <mesh
          filename="package://dual_arm_wo_wrist/meshes/L2_4.STL" />
      </geometry>
      <material
        name="">
        <color
          rgba="1 1 1 1" />
      </material>
    </visual>
    <collision>
      <origin
        xyz="0 0 0"
        rpy="0 0 0" />
      <geometry>
        <mesh
          filename="package://dual_arm_wo_wrist/meshes/L2_4.STL" />
      </geometry>
    </collision>
  </link>
  <joint
    name="J_24"
    type="revolute">
    <origin
      xyz="0.0266699999999995 0 0.0609600000000023"
      rpy="-1.5707963267949 0.697503960589116 -1.5707963267949" />
    <parent
      link="L2_3" />
    <child
      link="L2_4" />
    <axis
      xyz="0.238467796238905 0.284557429485269 0.928525809809128" />
  </joint>
</robot>